Workbook
Name scale_orig: Lifespan!$C$8
Name shape_orig: Lifespan!$C$7
Name shift_orig: Lifespan!$C$6

Sheet Intro
B4: Dynamic MFA Activity: Decades in Candy Town
B5: Reed Miller, reed.miller@maine.edu
B6: https://github.com/treedmiller/candytown-mfa
B8: This spreadsheet accompanies the handouts for this activity.
B10: GNU General Public License v3.0

Sheet Home Tracker Input Sheet
C2: Home Tracker: Construction Manager (CM) and Debris and Demolition Manager (DDM)
N4: Fill In: | T4: Construction
C5: Action | D5: Type | E5: 2000 | F5: 2010 | G5: 2020 | H5: 2030 | I5: 2040 | J5: 2050 | K5: 2060 | L5: 2070 | M5: 2080 | N5: B year | O5: D year | P5: Lifespan | S5: Material Fate | T5: Stays In Building | U5: Construction Scrap | V5: Total Materials | W5: Stays In Building | X5: Construction Scrap | Y5: Total Materials
B6: Fill in B, S, or D: | C6: 1 Sweet Street | D6: SF | E6: B | F6: S | G6: S | H6: S | I6: S | J6: S | K6: D | N6: 2000 | O6: 2060 | P6: 60 | S6: Type | T6: SF | U6: SF | V6: SF | W6: MF | X6: MF | Y6: MF
B7: Fill in B, S, or D: | C7: 2 Sweet Street | D7: SF | S7: Brick | T7: 2 | U7: 1 | V7: 3 | W7: 12 | X7: 2 | Y7: 14
B8: Fill in B, S, or D: | C8: 3 Sweet Street | D8: SF | S8: Wood | T8: 2.5 | U8: 0.5 | V8: 3 | W8: 0 | X8: 0 | Y8: 0
B9: Fill in B, S, or D: | C9: 4 Sweet Street | D9: SF | S9: Metal | T9: 1 | U9: 0 | V9: 1 | W9: 4 | X9: 0 | Y9: 4
B10: Fill in B, S, or D: | C10: 5 Sweet Street | D10: SF | S10: Glass | T10: 1 | U10: 0 | V10: 1 | W10: 2 | X10: 0 | Y10: 2
B11: Fill in B, S, or D: | C11: 6 Sweet Street | D11: SF | S11: Total | T11: 6.5 | U11: 1.5 | V11: 8 | W11: 18 | X11: 2 | Y11: 20
B12: Fill in B, S, or D: | C12: 1-3 Sugar Ave | D12: MF
B13: Fill in B, S, or D: | C13: 5-7 Sugar Ave | D13: MF | T13: Disposition After Demolition
B14: Fill in B, S, or D: | C14: 2-4 Sugar Ave | D14: MF | S14: Material Fate | T14: Total Debris | U14: Reuse/Recycled | V14: Combined Waste | W14: Total Debris | X14: Reuse/Recycled | Y14: Combined Waste
B15: Fill in B, S, or D: | C15: 6-8 Sugar Ave | D15: MF | S15: Type | T15: SF | U15: SF | V15: SF | W15: MF | X15: MF | Y15: MF
C16: Built (B) | D16: SF | E16: =COUNTIFS(E$6:E$15,"B",$D$6:$D$15,$D16) -> 1 | F16: =COUNTIFS(F$6:F$15,"B",$D$6:$D$15,$D16) -> 0 | G16: =COUNTIFS(G$6:G$15,"B",$D$6:$D$15,$D16) -> 0 | H16: =COUNTIFS(H$6:H$15,"B",$D$6:$D$15,$D16) -> 0 | I16: =COUNTIFS(I$6:I$15,"B",$D$6:$D$15,$D16) -> 0 | J16: =COUNTIFS(J$6:J$15,"B",$D$6:$D$15,$D16) -> 0 | K16: =COUNTIFS(K$6:K$15,"B",$D$6:$D$15,$D16) -> 0 | L16: =COUNTIFS(L$6:L$15,"B",$D$6:$D$15,$D16) -> 0 | M16: =COUNTIFS(M$6:M$15,"B",$D$6:$D$15,$D16) -> 0 | S16: Brick | T16: =SUM(U16:V16) -> 2 | U16: 1 | V16: =T7-U16 -> 1 | W16: =SUM(X16:Y16) -> 12 | X16: 6 | Y16: =W7-X16 -> 6
C17: Demolish (D) | D17: SF | E17: =COUNTIFS(E$6:E$15,"D",$D$6:$D$15,$D17) -> 0 | F17: =COUNTIFS(F$6:F$15,"D",$D$6:$D$15,$D17) -> 0 | G17: =COUNTIFS(G$6:G$15,"D",$D$6:$D$15,$D17) -> 0 | H17: =COUNTIFS(H$6:H$15,"D",$D$6:$D$15,$D17) -> 0 | I17: =COUNTIFS(I$6:I$15,"D",$D$6:$D$15,$D17) -> 0 | J17: =COUNTIFS(J$6:J$15,"D",$D$6:$D$15,$D17) -> 0 | K17: =COUNTIFS(K$6:K$15,"D",$D$6:$D$15,$D17) -> 1 | L17: =COUNTIFS(L$6:L$15,"D",$D$6:$D$15,$D17) -> 0 | M17: =COUNTIFS(M$6:M$15,"D",$D$6:$D$15,$D17) -> 0 | S17: Wood | T17: =SUM(U17:V17) -> 2.5 | U17: 2 | V17: =T8-U17 -> 0.5 | W17: =SUM(X17:Y17) -> 0 | X17: 0 | Y17: =W8-X17 -> 0
C18: Stock (S) calc. | D18: SF | E18: =E16-E17 -> 1 | F18: =F16-F17+E18 -> 1 | G18: =G16-G17+F18 -> 1 | H18: =H16-H17+G18 -> 1 | I18: =I16-I17+H18 -> 1 | J18: =J16-J17+I18 -> 1 | K18: =K16-K17+J18 -> 0 | L18: =L16-L17+K18 -> 0 | M18: =M16-M17+L18 -> 0 | S18: Metal | T18: =SUM(U18:V18) -> 1 | U18: 1 | V18: =T9-U18 -> 0 | W18: =SUM(X18:Y18) -> 4 | X18: 2 | Y18: =W9-X18 -> 2
C19: Stock (S) count | D19: SF | S19: Glass | T19: =SUM(U19:V19) -> 1 | U19: 0 | V19: =T10-U19 -> 1 | W19: =SUM(X19:Y19) -> 2 | X19: 0 | Y19: =W10-X19 -> 2
C20: Built (B) | D20: MF | E20: =COUNTIFS(E$6:E$15,"B",$D$6:$D$15,$D20) -> 0 | F20: =COUNTIFS(F$6:F$15,"B",$D$6:$D$15,$D20) -> 0 | G20: =COUNTIFS(G$6:G$15,"B",$D$6:$D$15,$D20) -> 0 | H20: =COUNTIFS(H$6:H$15,"B",$D$6:$D$15,$D20) -> 0 | I20: =COUNTIFS(I$6:I$15,"B",$D$6:$D$15,$D20) -> 0 | J20: =COUNTIFS(J$6:J$15,"B",$D$6:$D$15,$D20) -> 0 | K20: =COUNTIFS(K$6:K$15,"B",$D$6:$D$15,$D20) -> 0 | L20: =COUNTIFS(L$6:L$15,"B",$D$6:$D$15,$D20) -> 0 | M20: =COUNTIFS(M$6:M$15,"B",$D$6:$D$15,$D20) -> 0 | S20: Total | T20: =SUM(U20:V20) -> 6.5 | U20: 4 | V20: =T11-U20 -> 2.5 | W20: =SUM(X20:Y20) -> 18 | X20: 8 | Y20: =W11-X20 -> 10
C21: Demolish (D) | D21: MF | E21: =COUNTIFS(E$6:E$15,"D",$D$6:$D$15,$D21) -> 0 | F21: =COUNTIFS(F$6:F$15,"D",$D$6:$D$15,$D21) -> 0 | G21: =COUNTIFS(G$6:G$15,"D",$D$6:$D$15,$D21) -> 0 | H21: =COUNTIFS(H$6:H$15,"D",$D$6:$D$15,$D21) -> 0 | I21: =COUNTIFS(I$6:I$15,"D",$D$6:$D$15,$D21) -> 0 | J21: =COUNTIFS(J$6:J$15,"D",$D$6:$D$15,$D21) -> 0 | K21: =COUNTIFS(K$6:K$15,"D",$D$6:$D$15,$D21) -> 0 | L21: =COUNTIFS(L$6:L$15,"D",$D$6:$D$15,$D21) -> 0 | M21: =COUNTIFS(M$6:M$15,"D",$D$6:$D$15,$D21) -> 0
C22: Stock (S) calc. | D22: MF | E22: =E20-E21 -> 0 | F22: =F20-F21+E22 -> 0 | G22: =G20-G21+F22 -> 0 | H22: =H20-H21+G22 -> 0 | I22: =I20-I21+H22 -> 0 | J22: =J20-J21+I22 -> 0 | K22: =K20-K21+J22 -> 0 | L22: =L20-L21+K22 -> 0 | M22: =M20-M21+L22 -> 0
C23: Stock (S) count | D23: MF
C24: Stock (S) sum | D24: Total | E24: =E18+E22 -> 1 | F24: =F18+F22 -> 1 | G24: =G18+G22 -> 1 | H24: =H18+H22 -> 1 | I24: =I18+I22 -> 1 | J24: =J18+J22 -> 1 | K24: =K18+K22 -> 0 | L24: =L18+L22 -> 0 | M24: =M18+M22 -> 0
D26: Link to results: | E26: Materials for Construction | I26: Construction Scrap Materials
E27: Materials in Stock
E28: Materials from Demolished Buildings | I28: Materials for Reuse / Recycling
C30: Materials for Construction: SF | W30: Construction Scrap: SF
B31: Total Materials | C31: Type | D31: Material | E31: 2000 | F31: 2010 | G31: 2020 | H31: 2030 | I31: 2040 | J31: 2050 | K31: 2060 | L31: 2070 | M31: 2080 | V31: Construction Scrap | W31: Type | X31: Material | Y31: 2000 | Z31: 2010 | AA31: 2020 | AB31: 2030 | AC31: 2040 | AD31: 2050 | AE31: 2060 | AF31: 2070 | AG31: 2080
B32: 3 | C32: SF | D32: Brick | E32: =$B32*E$16 -> 3 | F32: =$B32*F$16 -> 0 | G32: =$B32*G$16 -> 0 | H32: =$B32*H$16 -> 0 | I32: =$B32*I$16 -> 0 | J32: =$B32*J$16 -> 0 | K32: =$B32*K$16 -> 0 | L32: =$B32*L$16 -> 0 | M32: =$B32*M$16 -> 0 | V32: 1 | W32: SF | X32: Brick | Y32: =$V32*E$16 -> 1 | Z32: =$V32*F$16 -> 0 | AA32: =$V32*G$16 -> 0 | AB32: =$V32*H$16 -> 0 | AC32: =$V32*I$16 -> 0 | AD32: =$V32*J$16 -> 0 | AE32: =$V32*K$16 -> 0 | AF32: =$V32*L$16 -> 0 | AG32: =$V32*M$16 -> 0
B33: 3 | C33: SF | D33: Wood | E33: =$B33*E$16 -> 3 | F33: =$B33*F$16 -> 0 | G33: =$B33*G$16 -> 0 | H33: =$B33*H$16 -> 0 | I33: =$B33*I$16 -> 0 | J33: =$B33*J$16 -> 0 | K33: =$B33*K$16 -> 0 | L33: =$B33*L$16 -> 0 | M33: =$B33*M$16 -> 0 | V33: 0.5 | W33: SF | X33: Wood | Y33: =$V33*E$16 -> 0.5 | Z33: =$V33*F$16 -> 0 | AA33: =$V33*G$16 -> 0 | AB33: =$V33*H$16 -> 0 | AC33: =$V33*I$16 -> 0 | AD33: =$V33*J$16 -> 0 | AE33: =$V33*K$16 -> 0 | AF33: =$V33*L$16 -> 0 | AG33: =$V33*M$16 -> 0
B34: 1 | C34: SF | D34: Metal | E34: =$B34*E$16 -> 1 | F34: =$B34*F$16 -> 0 | G34: =$B34*G$16 -> 0 | H34: =$B34*H$16 -> 0 | I34: =$B34*I$16 -> 0 | J34: =$B34*J$16 -> 0 | K34: =$B34*K$16 -> 0 | L34: =$B34*L$16 -> 0 | M34: =$B34*M$16 -> 0 | V34: 0 | W34: SF | X34: Metal | Y34: =$V34*E$16 -> 0 | Z34: =$V34*F$16 -> 0 | AA34: =$V34*G$16 -> 0 | AB34: =$V34*H$16 -> 0 | AC34: =$V34*I$16 -> 0 | AD34: =$V34*J$16 -> 0 | AE34: =$V34*K$16 -> 0 | AF34: =$V34*L$16 -> 0 | AG34: =$V34*M$16 -> 0
B35: 1 | C35: SF | D35: Glass | E35: =$B35*E$16 -> 1 | F35: =$B35*F$16 -> 0 | G35: =$B35*G$16 -> 0 | H35: =$B35*H$16 -> 0 | I35: =$B35*I$16 -> 0 | J35: =$B35*J$16 -> 0 | K35: =$B35*K$16 -> 0 | L35: =$B35*L$16 -> 0 | M35: =$B35*M$16 -> 0 | V35: 0 | W35: SF | X35: Glass | Y35: =$V35*E$16 -> 0 | Z35: =$V35*F$16 -> 0 | AA35: =$V35*G$16 -> 0 | AB35: =$V35*H$16 -> 0 | AC35: =$V35*I$16 -> 0 | AD35: =$V35*J$16 -> 0 | AE35: =$V35*K$16 -> 0 | AF35: =$V35*L$16 -> 0 | AG35: =$V35*M$16 -> 0
B36: 8 | C36: SF | D36: Total | E36: =$B36*E$16 -> 8 | F36: =$B36*F$16 -> 0 | G36: =$B36*G$16 -> 0 | H36: =$B36*H$16 -> 0 | I36: =$B36*I$16 -> 0 | J36: =$B36*J$16 -> 0 | K36: =$B36*K$16 -> 0 | L36: =$B36*L$16 -> 0 | M36: =$B36*M$16 -> 0 | V36: 1.5 | W36: SF | X36: Total | Y36: =$V36*E$16 -> 1.5 | Z36: =$V36*F$16 -> 0 | AA36: =$V36*G$16 -> 0 | AB36: =$V36*H$16 -> 0 | AC36: =$V36*I$16 -> 0 | AD36: =$V36*J$16 -> 0 | AE36: =$V36*K$16 -> 0 | AF36: =$V36*L$16 -> 0 | AG36: =$V36*M$16 -> 0
C38: Materials for Construction: MF | W38: Construction Scrap: MF
B39: Total Materials | C39: Type | D39: Material | E39: 2000 | F39: 2010 | G39: 2020 | H39: 2030 | I39: 2040 | J39: 2050 | K39: 2060 | L39: 2070 | M39: 2080 | V39: Construction Scrap | W39: Type | X39: Material | Y39: 2000 | Z39: 2010 | AA39: 2020 | AB39: 2030 | AC39: 2040 | AD39: 2050 | AE39: 2060 | AF39: 2070 | AG39: 2080
B40: 14 | C40: MF | D40: Brick | E40: =$B40*E$20 -> 0 | F40: =$B40*F$20 -> 0 | G40: =$B40*G$20 -> 0 | H40: =$B40*H$20 -> 0 | I40: =$B40*I$20 -> 0 | J40: =$B40*J$20 -> 0 | K40: =$B40*K$20 -> 0 | L40: =$B40*L$20 -> 0 | M40: =$B40*M$20 -> 0 | V40: 2 | W40: MF | X40: Brick | Y40: =$V40*E$20 -> 0 | Z40: =$V40*F$20 -> 0 | AA40: =$V40*G$20 -> 0 | AB40: =$V40*H$20 -> 0 | AC40: =$V40*I$20 -> 0 | AD40: =$V40*J$20 -> 0 | AE40: =$V40*K$20 -> 0 | AF40: =$V40*L$20 -> 0 | AG40: =$V40*M$20 -> 0
B41: 0 | C41: MF | D41: Wood | E41: =$B41*E$20 -> 0 | F41: =$B41*F$20 -> 0 | G41: =$B41*G$20 -> 0 | H41: =$B41*H$20 -> 0 | I41: =$B41*I$20 -> 0 | J41: =$B41*J$20 -> 0 | K41: =$B41*K$20 -> 0 | L41: =$B41*L$20 -> 0 | M41: =$B41*M$20 -> 0 | V41: 0 | W41: MF | X41: Wood | Y41: =$V41*E$20 -> 0 | Z41: =$V41*F$20 -> 0 | AA41: =$V41*G$20 -> 0 | AB41: =$V41*H$20 -> 0 | AC41: =$V41*I$20 -> 0 | AD41: =$V41*J$20 -> 0 | AE41: =$V41*K$20 -> 0 | AF41: =$V41*L$20 -> 0 | AG41: =$V41*M$20 -> 0
B42: 4 | C42: MF | D42: Metal | E42: =$B42*E$20 -> 0 | F42: =$B42*F$20 -> 0 | G42: =$B42*G$20 -> 0 | H42: =$B42*H$20 -> 0 | I42: =$B42*I$20 -> 0 | J42: =$B42*J$20 -> 0 | K42: =$B42*K$20 -> 0 | L42: =$B42*L$20 -> 0 | M42: =$B42*M$20 -> 0 | V42: 0 | W42: MF | X42: Metal | Y42: =$V42*E$20 -> 0 | Z42: =$V42*F$20 -> 0 | AA42: =$V42*G$20 -> 0 | AB42: =$V42*H$20 -> 0 | AC42: =$V42*I$20 -> 0 | AD42: =$V42*J$20 -> 0 | AE42: =$V42*K$20 -> 0 | AF42: =$V42*L$20 -> 0 | AG42: =$V42*M$20 -> 0
B43: 2 | C43: MF | D43: Glass | E43: =$B43*E$20 -> 0 | F43: =$B43*F$20 -> 0 | G43: =$B43*G$20 -> 0 | H43: =$B43*H$20 -> 0 | I43: =$B43*I$20 -> 0 | J43: =$B43*J$20 -> 0 | K43: =$B43*K$20 -> 0 | L43: =$B43*L$20 -> 0 | M43: =$B43*M$20 -> 0 | V43: 0 | W43: MF | X43: Glass | Y43: =$V43*E$20 -> 0 | Z43: =$V43*F$20 -> 0 | AA43: =$V43*G$20 -> 0 | AB43: =$V43*H$20 -> 0 | AC43: =$V43*I$20 -> 0 | AD43: =$V43*J$20 -> 0 | AE43: =$V43*K$20 -> 0 | AF43: =$V43*L$20 -> 0 | AG43: =$V43*M$20 -> 0
B44: 20 | C44: MF | D44: Total | E44: =$B44*E$20 -> 0 | F44: =$B44*F$20 -> 0 | G44: =$B44*G$20 -> 0 | H44: =$B44*H$20 -> 0 | I44: =$B44*I$20 -> 0 | J44: =$B44*J$20 -> 0 | K44: =$B44*K$20 -> 0 | L44: =$B44*L$20 -> 0 | M44: =$B44*M$20 -> 0 | V44: 2 | W44: MF | X44: Total | Y44: =$V44*E$20 -> 0 | Z44: =$V44*F$20 -> 0 | AA44: =$V44*G$20 -> 0 | AB44: =$V44*H$20 -> 0 | AC44: =$V44*I$20 -> 0 | AD44: =$V44*J$20 -> 0 | AE44: =$V44*K$20 -> 0 | AF44: =$V44*L$20 -> 0 | AG44: =$V44*M$20 -> 0
C46: Materials for Construction: Both | W46: Construction Scrap: Both
...

Sheet Flow Tracker Input Sheet
B2: Flow Tracker: Materials Warehouse Manager (MWM) | Y2: Challenge: make charts like these for particular materials!
C3: Fill In: | D3: Fill In: | G3: Fill In: | H3: Fill In: | K3: Fill In: | L3: Fill In: | O3: Fill In: | P3: Fill In:
C4: Brick | G4: Wood | K4: Metal | O4: Glass | S4: Total
B5: Year | C5: Flow In | D5: Flow Out | E5: Stock Δ | F5: Stock | G5: Flow In | H5: Flow Out | I5: Stock Δ | J5: Stock | K5: Flow In | L5: Flow Out | M5: Stock Δ | N5: Stock | O5: Flow In | P5: Flow Out | Q5: Stock Δ | R5: Stock | S5: Flow In | T5: Flow Out | U5: Stock Δ | V5: Stock
B6: 2000 | E6: =C6-D6 -> 0 | F6: =E6 -> 0 | I6: =G6-H6 -> 0 | J6: =I6 -> 0 | M6: =K6-L6 -> 0 | N6: =M6 -> 0 | Q6: =O6-P6 -> 0 | R6: =Q6 -> 0 | S6: =SUMIF($C$5:$R$5,S$5,$C6:$R6) -> 0 | T6: =-SUMIF($C$5:$R$5,T$5,$C6:$R6) -> 0 | U6: =SUMIF($C$5:$R$5,U$5,$C6:$R6) -> 0 | V6: =SUMIF($C$5:$R$5,V$5,$C6:$R6) -> 0
B7: 2010 | E7: =C7-D7 -> 0 | F7: =F6+E7 -> 0 | I7: =G7-H7 -> 0 | J7: =J6+I7 -> 0 | M7: =K7-L7 -> 0 | N7: =N6+M7 -> 0 | Q7: =O7-P7 -> 0 | R7: =R6+Q7 -> 0 | S7: =SUMIF($C$5:$R$5,S$5,$C7:$R7) -> 0 | T7: =-SUMIF($C$5:$R$5,T$5,$C7:$R7) -> 0 | U7: =SUMIF($C$5:$R$5,U$5,$C7:$R7) -> 0 | V7: =SUMIF($C$5:$R$5,V$5,$C7:$R7) -> 0
B8: 2020 | E8: =C8-D8 -> 0 | F8: =F7+E8 -> 0 | I8: =G8-H8 -> 0 | J8: =J7+I8 -> 0 | M8: =K8-L8 -> 0 | N8: =N7+M8 -> 0 | Q8: =O8-P8 -> 0 | R8: =R7+Q8 -> 0 | S8: =SUMIF($C$5:$R$5,S$5,$C8:$R8) -> 0 | T8: =-SUMIF($C$5:$R$5,T$5,$C8:$R8) -> 0 | U8: =SUMIF($C$5:$R$5,U$5,$C8:$R8) -> 0 | V8: =SUMIF($C$5:$R$5,V$5,$C8:$R8) -> 0
B9: 2030 | E9: =C9-D9 -> 0 | F9: =F8+E9 -> 0 | I9: =G9-H9 -> 0 | J9: =J8+I9 -> 0 | M9: =K9-L9 -> 0 | N9: =N8+M9 -> 0 | Q9: =O9-P9 -> 0 | R9: =R8+Q9 -> 0 | S9: =SUMIF($C$5:$R$5,S$5,$C9:$R9) -> 0 | T9: =-SUMIF($C$5:$R$5,T$5,$C9:$R9) -> 0 | U9: =SUMIF($C$5:$R$5,U$5,$C9:$R9) -> 0 | V9: =SUMIF($C$5:$R$5,V$5,$C9:$R9) -> 0
B10: 2040 | E10: =C10-D10 -> 0 | F10: =F9+E10 -> 0 | I10: =G10-H10 -> 0 | J10: =J9+I10 -> 0 | M10: =K10-L10 -> 0 | N10: =N9+M10 -> 0 | Q10: =O10-P10 -> 0 | R10: =R9+Q10 -> 0 | S10: =SUMIF($C$5:$R$5,S$5,$C10:$R10) -> 0 | T10: =-SUMIF($C$5:$R$5,T$5,$C10:$R10) -> 0 | U10: =SUMIF($C$5:$R$5,U$5,$C10:$R10) -> 0 | V10: =SUMIF($C$5:$R$5,V$5,$C10:$R10) -> 0
B11: 2050 | E11: =C11-D11 -> 0 | F11: =F10+E11 -> 0 | I11: =G11-H11 -> 0 | J11: =J10+I11 -> 0 | M11: =K11-L11 -> 0 | N11: =N10+M11 -> 0 | Q11: =O11-P11 -> 0 | R11: =R10+Q11 -> 0 | S11: =SUMIF($C$5:$R$5,S$5,$C11:$R11) -> 0 | T11: =-SUMIF($C$5:$R$5,T$5,$C11:$R11) -> 0 | U11: =SUMIF($C$5:$R$5,U$5,$C11:$R11) -> 0 | V11: =SUMIF($C$5:$R$5,V$5,$C11:$R11) -> 0
B12: 2060 | E12: =C12-D12 -> 0 | F12: =F11+E12 -> 0 | I12: =G12-H12 -> 0 | J12: =J11+I12 -> 0 | M12: =K12-L12 -> 0 | N12: =N11+M12 -> 0 | Q12: =O12-P12 -> 0 | R12: =R11+Q12 -> 0 | S12: =SUMIF($C$5:$R$5,S$5,$C12:$R12) -> 0 | T12: =-SUMIF($C$5:$R$5,T$5,$C12:$R12) -> 0 | U12: =SUMIF($C$5:$R$5,U$5,$C12:$R12) -> 0 | V12: =SUMIF($C$5:$R$5,V$5,$C12:$R12) -> 0
B13: 2070 | E13: =C13-D13 -> 0 | F13: =F12+E13 -> 0 | I13: =G13-H13 -> 0 | J13: =J12+I13 -> 0 | M13: =K13-L13 -> 0 | N13: =N12+M13 -> 0 | Q13: =O13-P13 -> 0 | R13: =R12+Q13 -> 0 | S13: =SUMIF($C$5:$R$5,S$5,$C13:$R13) -> 0 | T13: =-SUMIF($C$5:$R$5,T$5,$C13:$R13) -> 0 | U13: =SUMIF($C$5:$R$5,U$5,$C13:$R13) -> 0 | V13: =SUMIF($C$5:$R$5,V$5,$C13:$R13) -> 0
B14: 2080 | E14: =C14-D14 -> 0 | F14: =F13+E14 -> 0 | I14: =G14-H14 -> 0 | J14: =J13+I14 -> 0 | M14: =K14-L14 -> 0 | N14: =N13+M14 -> 0 | Q14: =O14-P14 -> 0 | R14: =R13+Q14 -> 0 | S14: =SUMIF($C$5:$R$5,S$5,$C14:$R14) -> 0 | T14: =-SUMIF($C$5:$R$5,T$5,$C14:$R14) -> 0 | U14: =SUMIF($C$5:$R$5,U$5,$C14:$R14) -> 0 | V14: =SUMIF($C$5:$R$5,V$5,$C14:$R14) -> 0
B15: Total | C15: =SUM(C6:C14) -> 0 | D15: =SUM(D6:D14) -> 0 | E15: =SUM(E6:E14) -> 0 | F15: N/A | G15: =SUM(G6:G14) -> 0 | H15: =SUM(H6:H14) -> 0 | I15: =SUM(I6:I14) -> 0 | J15: N/A | K15: =SUM(K6:K14) -> 0 | L15: =SUM(L6:L14) -> 0 | M15: =SUM(M6:M14) -> 0 | N15: N/A | O15: =SUM(O6:O14) -> 0 | P15: =SUM(P6:P14) -> 0 | Q15: =SUM(Q6:Q14) -> 0 | R15: N/A | S15: =SUMIF($C$5:$R$5,S$5,$C15:$R15) -> 0 | T15: =-SUMIF($C$5:$R$5,T$5,$C15:$R15) -> 0 | U15: =SUMIF($C$5:$R$5,U$5,$C15:$R15) -> 0
B19: Flow Tracker: Waste & Recycling Manager (WRM)
C21: Brick for Reuse | G21: Wood for Reuse | K21: Metal for Recycling | O21: Combined Scrap &
O22: Debris for Landfill | S22: Total
B23: Year | C23: Flow In | D23: Flow Out | E23: Stock Δ | F23: Stock | G23: Flow In | H23: Flow Out | I23: Stock Δ | J23: Stock | K23: Flow In | L23: Flow Out | M23: Stock Δ | N23: Stock | O23: Flow In | P23: Flow Out | Q23: Stock Δ | R23: Stock | S23: Flow In | T23: Flow Out | U23: Stock Δ | V23: Stock
B24: 2000 | E24: =C24-D24 -> 0 | F24: =E24 -> 0 | I24: =G24-H24 -> 0 | J24: =I24 -> 0 | M24: =K24-L24 -> 0 | N24: =M24 -> 0 | Q24: =O24-P24 -> 0 | R24: =Q24 -> 0 | S24: =SUMIF($C$5:$R$5,S$5,$C24:$R24) -> 0 | T24: =-SUMIF($C$5:$R$5,T$5,$C24:$R24) -> 0 | U24: =SUMIF($C$5:$R$5,U$5,$C24:$R24) -> 0 | V24: =SUMIF($C$5:$R$5,V$5,$C24:$R24) -> 0
B25: 2010 | E25: =C25-D25 -> 0 | F25: =F24+E25 -> 0 | I25: =G25-H25 -> 0 | J25: =J24+I25 -> 0 | M25: =K25-L25 -> 0 | N25: =N24+M25 -> 0 | Q25: =O25-P25 -> 0 | R25: =R24+Q25 -> 0 | S25: =SUMIF($C$5:$R$5,S$5,$C25:$R25) -> 0 | T25: =-SUMIF($C$5:$R$5,T$5,$C25:$R25) -> 0 | U25: =SUMIF($C$5:$R$5,U$5,$C25:$R25) -> 0 | V25: =SUMIF($C$5:$R$5,V$5,$C25:$R25) -> 0
B26: 2020 | E26: =C26-D26 -> 0 | F26: =F25+E26 -> 0 | I26: =G26-H26 -> 0 | J26: =J25+I26 -> 0 | M26: =K26-L26 -> 0 | N26: =N25+M26 -> 0 | Q26: =O26-P26 -> 0 | R26: =R25+Q26 -> 0 | S26: =SUMIF($C$5:$R$5,S$5,$C26:$R26) -> 0 | T26: =-SUMIF($C$5:$R$5,T$5,$C26:$R26) -> 0 | U26: =SUMIF($C$5:$R$5,U$5,$C26:$R26) -> 0 | V26: =SUMIF($C$5:$R$5,V$5,$C26:$R26) -> 0
B27: 2030 | E27: =C27-D27 -> 0 | F27: =F26+E27 -> 0 | I27: =G27-H27 -> 0 | J27: =J26+I27 -> 0 | M27: =K27-L27 -> 0 | N27: =N26+M27 -> 0 | Q27: =O27-P27 -> 0 | R27: =R26+Q27 -> 0 | S27: =SUMIF($C$5:$R$5,S$5,$C27:$R27) -> 0 | T27: =-SUMIF($C$5:$R$5,T$5,$C27:$R27) -> 0 | U27: =SUMIF($C$5:$R$5,U$5,$C27:$R27) -> 0 | V27: =SUMIF($C$5:$R$5,V$5,$C27:$R27) -> 0
B28: 2040 | E28: =C28-D28 -> 0 | F28: =F27+E28 -> 0 | I28: =G28-H28 -> 0 | J28: =J27+I28 -> 0 | M28: =K28-L28 -> 0 | N28: =N27+M28 -> 0 | Q28: =O28-P28 -> 0 | R28: =R27+Q28 -> 0 | S28: =SUMIF($C$5:$R$5,S$5,$C28:$R28) -> 0 | T28: =-SUMIF($C$5:$R$5,T$5,$C28:$R28) -> 0 | U28: =SUMIF($C$5:$R$5,U$5,$C28:$R28) -> 0 | V28: =SUMIF($C$5:$R$5,V$5,$C28:$R28) -> 0
B29: 2050 | E29: =C29-D29 -> 0 | F29: =F28+E29 -> 0 | I29: =G29-H29 -> 0 | J29: =J28+I29 -> 0 | M29: =K29-L29 -> 0 | N29: =N28+M29 -> 0 | Q29: =O29-P29 -> 0 | R29: =R28+Q29 -> 0 | S29: =SUMIF($C$5:$R$5,S$5,$C29:$R29) -> 0 | T29: =-SUMIF($C$5:$R$5,T$5,$C29:$R29) -> 0 | U29: =SUMIF($C$5:$R$5,U$5,$C29:$R29) -> 0 | V29: =SUMIF($C$5:$R$5,V$5,$C29:$R29) -> 0
B30: 2060 | E30: =C30-D30 -> 0 | F30: =F29+E30 -> 0 | I30: =G30-H30 -> 0 | J30: =J29+I30 -> 0 | M30: =K30-L30 -> 0 | N30: =N29+M30 -> 0 | Q30: =O30-P30 -> 0 | R30: =R29+Q30 -> 0 | S30: =SUMIF($C$5:$R$5,S$5,$C30:$R30) -> 0 | T30: =-SUMIF($C$5:$R$5,T$5,$C30:$R30) -> 0 | U30: =SUMIF($C$5:$R$5,U$5,$C30:$R30) -> 0 | V30: =SUMIF($C$5:$R$5,V$5,$C30:$R30) -> 0
B31: 2070 | E31: =C31-D31 -> 0 | F31: =F30+E31 -> 0 | I31: =G31-H31 -> 0 | J31: =J30+I31 -> 0 | M31: =K31-L31 -> 0 | N31: =N30+M31 -> 0 | Q31: =O31-P31 -> 0 | R31: =R30+Q31 -> 0 | S31: =SUMIF($C$5:$R$5,S$5,$C31:$R31) -> 0 | T31: =-SUMIF($C$5:$R$5,T$5,$C31:$R31) -> 0 | U31: =SUMIF($C$5:$R$5,U$5,$C31:$R31) -> 0 | V31: =SUMIF($C$5:$R$5,V$5,$C31:$R31) -> 0
B32: 2080 | E32: =C32-D32 -> 0 | F32: =F31+E32 -> 0 | I32: =G32-H32 -> 0 | J32: =J31+I32 -> 0 | M32: =K32-L32 -> 0 | N32: =N31+M32 -> 0 | Q32: =O32-P32 -> 0 | R32: =R31+Q32 -> 0 | S32: =SUMIF($C$5:$R$5,S$5,$C32:$R32) -> 0 | T32: =-SUMIF($C$5:$R$5,T$5,$C32:$R32) -> 0 | U32: =SUMIF($C$5:$R$5,U$5,$C32:$R32) -> 0 | V32: =SUMIF($C$5:$R$5,V$5,$C32:$R32) -> 0
B33: Total | C33: =SUM(C24:C32) -> 0 | D33: =SUM(D24:D32) -> 0 | E33: =SUM(E24:E32) -> 0 | F33: N/A | G33: =SUM(G24:G32) -> 0 | H33: =SUM(H24:H32) -> 0 | I33: =SUM(I24:I32) -> 0 | J33: N/A | K33: =SUM(K24:K32) -> 0 | L33: =SUM(L24:L32) -> 0 | M33: =SUM(M24:M32) -> 0 | N33: N/A | O33: =SUM(O24:O32) -> 0 | P33: =SUM(P24:P32) -> 0 | Q33: =SUM(Q24:Q32) -> 0 | R33: N/A | S33: =SUMIF($C$5:$R$5,S$5,$C33:$R33) -> 0 | T33: =-SUMIF($C$5:$R$5,T$5,$C33:$R33) -> 0 | U33: =SUMIF($C$5:$R$5,U$5,$C33:$R33) -> 0
B36: Flow Tracker: Construction Manager (CM) and Debris and Demolition Manager (DDM)
C38: Brick | G38: Wood | K38: Metal | O38: Glass | S38: Total
B39: Year | C39: Flow In | D39: Flow Out | E39: Stock Δ | F39: Stock | G39: Flow In | H39: Flow Out | I39: Stock Δ | J39: Stock | K39: Flow In | L39: Flow Out | M39: Stock Δ | N39: Stock | O39: Flow In | P39: Flow Out | Q39: Stock Δ | R39: Stock | S39: Flow In | T39: Flow Out | U39: Stock Δ | V39: Stock
B40: 2000 | E40: =C40-D40 -> 0 | F40: =E40 -> 0 | I40: =G40-H40 -> 0 | J40: =I40 -> 0 | M40: =K40-L40 -> 0 | N40: =M40 -> 0 | Q40: =O40-P40 -> 0 | R40: =Q40 -> 0 | S40: =SUMIF($C$5:$R$5,S$5,$C40:$R40) -> 0 | T40: =-SUMIF($C$5:$R$5,T$5,$C40:$R40) -> 0 | U40: =SUMIF($C$5:$R$5,U$5,$C40:$R40) -> 0 | V40: =SUMIF($C$5:$R$5,V$5,$C40:$R40) -> 0
B41: 2010 | E41: =C41-D41 -> 0 | F41: =F40+E41 -> 0 | I41: =G41-H41 -> 0 | J41: =J40+I41 -> 0 | M41: =K41-L41 -> 0 | N41: =N40+M41 -> 0 | Q41: =O41-P41 -> 0 | R41: =R40+Q41 -> 0 | S41: =SUMIF($C$5:$R$5,S$5,$C41:$R41) -> 0 | T41: =-SUMIF($C$5:$R$5,T$5,$C41:$R41) -> 0 | U41: =SUMIF($C$5:$R$5,U$5,$C41:$R41) -> 0 | V41: =SUMIF($C$5:$R$5,V$5,$C41:$R41) -> 0
B42: 2020 | E42: =C42-D42 -> 0 | F42: =F41+E42 -> 0 | I42: =G42-H42 -> 0 | J42: =J41+I42 -> 0 | M42: =K42-L42 -> 0 | N42: =N41+M42 -> 0 | Q42: =O42-P42 -> 0 | R42: =R41+Q42 -> 0 | S42: =SUMIF($C$5:$R$5,S$5,$C42:$R42) -> 0 | T42: =-SUMIF($C$5:$R$5,T$5,$C42:$R42) -> 0 | U42: =SUMIF($C$5:$R$5,U$5,$C42:$R42) -> 0 | V42: =SUMIF($C$5:$R$5,V$5,$C42:$R42) -> 0
B43: 2030 | E43: =C43-D43 -> 0 | F43: =F42+E43 -> 0 | I43: =G43-H43 -> 0 | J43: =J42+I43 -> 0 | M43: =K43-L43 -> 0 | N43: =N42+M43 -> 0 | Q43: =O43-P43 -> 0 | R43: =R42+Q43 -> 0 | S43: =SUMIF($C$5:$R$5,S$5,$C43:$R43) -> 0 | T43: =-SUMIF($C$5:$R$5,T$5,$C43:$R43) -> 0 | U43: =SUMIF($C$5:$R$5,U$5,$C43:$R43) -> 0 | V43: =SUMIF($C$5:$R$5,V$5,$C43:$R43) -> 0
B44: 2040 | E44: =C44-D44 -> 0 | F44: =F43+E44 -> 0 | I44: =G44-H44 -> 0 | J44: =J43+I44 -> 0 | M44: =K44-L44 -> 0 | N44: =N43+M44 -> 0 | Q44: =O44-P44 -> 0 | R44: =R43+Q44 -> 0 | S44: =SUMIF($C$5:$R$5,S$5,$C44:$R44) -> 0 | T44: =-SUMIF($C$5:$R$5,T$5,$C44:$R44) -> 0 | U44: =SUMIF($C$5:$R$5,U$5,$C44:$R44) -> 0 | V44: =SUMIF($C$5:$R$5,V$5,$C44:$R44) -> 0
B45: 2050 | E45: =C45-D45 -> 0 | F45: =F44+E45 -> 0 | I45: =G45-H45 -> 0 | J45: =J44+I45 -> 0 | M45: =K45-L45 -> 0 | N45: =N44+M45 -> 0 | Q45: =O45-P45 -> 0 | R45: =R44+Q45 -> 0 | S45: =SUMIF($C$5:$R$5,S$5,$C45:$R45) -> 0 | T45: =-SUMIF($C$5:$R$5,T$5,$C45:$R45) -> 0 | U45: =SUMIF($C$5:$R$5,U$5,$C45:$R45) -> 0 | V45: =SUMIF($C$5:$R$5,V$5,$C45:$R45) -> 0
B46: 2060 | E46: =C46-D46 -> 0 | F46: =F45+E46 -> 0 | I46: =G46-H46 -> 0 | J46: =J45+I46 -> 0 | M46: =K46-L46 -> 0 | N46: =N45+M46 -> 0 | Q46: =O46-P46 -> 0 | R46: =R45+Q46 -> 0 | S46: =SUMIF($C$5:$R$5,S$5,$C46:$R46) -> 0 | T46: =-SUMIF($C$5:$R$5,T$5,$C46:$R46) -> 0 | U46: =SUMIF($C$5:$R$5,U$5,$C46:$R46) -> 0 | V46: =SUMIF($C$5:$R$5,V$5,$C46:$R46) -> 0
B47: 2070 | E47: =C47-D47 -> 0 | F47: =F46+E47 -> 0 | I47: =G47-H47 -> 0 | J47: =J46+I47 -> 0 | M47: =K47-L47 -> 0 | N47: =N46+M47 -> 0 | Q47: =O47-P47 -> 0 | R47: =R46+Q47 -> 0 | S47: =SUMIF($C$5:$R$5,S$5,$C47:$R47) -> 0 | T47: =-SUMIF($C$5:$R$5,T$5,$C47:$R47) -> 0 | U47: =SUMIF($C$5:$R$5,U$5,$C47:$R47) -> 0 | V47: =SUMIF($C$5:$R$5,V$5,$C47:$R47) -> 0
B48: 2080 | E48: =C48-D48 -> 0 | F48: =F47+E48 -> 0 | I48: =G48-H48 -> 0 | J48: =J47+I48 -> 0 | M48: =K48-L48 -> 0 | N48: =N47+M48 -> 0 | Q48: =O48-P48 -> 0 | R48: =R47+Q48 -> 0 | S48: =SUMIF($C$5:$R$5,S$5,$C48:$R48) -> 0 | T48: =-SUMIF($C$5:$R$5,T$5,$C48:$R48) -> 0 | U48: =SUMIF($C$5:$R$5,U$5,$C48:$R48) -> 0 | V48: =SUMIF($C$5:$R$5,V$5,$C48:$R48) -> 0
...

Sheet Hummus Town, growing stock
B1: Building Designers in Hummus Town want to explore what would happen if they make their buildings last longer, by shifting the lifespan later.
B2: Assume they build an initial stock of homes in 2080, and then stock increases at a fixed growth rate each decade.
B3: Change the "Years Shifted Later", the "Initial Stock of Homes" (cell G15), and the "Decadal growth rate of stock" (cell L15)
B5: Weibull Parameters | E5: Candy Town Lifespan Distribution
B6: shift | C6: =shift_orig -> 10 | E6: Lifespan | F6: 0 | G6: 10 | H6: 20 | I6: 30 | J6: 40 | K6: 50 | L6: 60 | M6: 70 | N6: 80 | O6: 90 | P6: 100 | Q6: 110 | R6: 120 | S6: 130 | T6: 140 | U6: 150 | V6: 160 | W6: 170 | X6: 180 | Y6: 190 | Z6: 200
B7: shape | C7: =shape_orig -> 2 | E7: Cumul. % | F7: =IF(F$6<shift_orig,0,_xlfn.WEIBULL.DIST(F$6-shift_orig,shape_orig,scale_orig,TRUE)) -> 0 | G7: =IF(G$6<shift_orig,0,_xlfn.WEIBULL.DIST(G$6-shift_orig,shape_orig,scale_orig,TRUE)) -> 0 | H7: =IF(H$6<shift_orig,0,_xlfn.WEIBULL.DIST(H$6-shift_orig,shape_orig,scale_orig,TRUE)) -> 0.10516068 | I7: =IF(I$6<shift_orig,0,_xlfn.WEIBULL.DIST(I$6-shift_orig,shape_orig,scale_orig,TRUE)) -> 0.35881961 | J7: =IF(J$6<shift_orig,0,_xlfn.WEIBULL.DIST(J$6-shift_orig,shape_orig,scale_orig,TRUE)) -> 0.63212056 | K7: =IF(K$6<shift_orig,0,_xlfn.WEIBULL.DIST(K$6-shift_orig,shape_orig,scale_orig,TRUE)) -> 0.83098668 | L7: =IF(L$6<shift_orig,0,_xlfn.WEIBULL.DIST(L$6-shift_orig,shape_orig,scale_orig,TRUE)) -> 0.93782348 | M7: =IF(M$6<shift_orig,0,_xlfn.WEIBULL.DIST(M$6-shift_orig,shape_orig,scale_orig,TRUE)) -> 0.98168436 | ... Z7: =IF(Z$6<shift_orig,0,_xlfn.WEIBULL.DIST(Z$6-shift_orig,shape_orig,scale_orig,TRUE)) -> 1
B8: scale | C8: =scale_orig -> 30 | E8: Discrete % | F8: 0 | G8: =G7-F7 -> 0 | H8: =H7-G7 -> 0.10516068 | I8: =I7-H7 -> 0.25365893 | J8: =J7-I7 -> 0.27330095 | K8: =K7-J7 -> 0.19886613 | L8: =L7-K7 -> 0.10683679 | M8: =M7-L7 -> 0.043860885 | N8: =N7-M7 -> 0.013995399 | ... Z8: =Z7-Y7 -> 0
E10: Years Shifted Later: | G10: 30 | H10: (must be multiple of 10)
E11: Hummus Town Longer Lifespan Distribution
E12: Lifespan | F12: 0 | G12: 10 | H12: 20 | I12: 30 | J12: 40 | K12: 50 | L12: 60 | M12: 70 | N12: 80 | O12: 90 | P12: 100 | Q12: 110 | R12: 120 | S12: 130 | T12: 140 | U12: 150 | V12: 160 | W12: 170 | X12: 180 | Y12: 190 | Z12: 200
E13: Discrete % | F13: =IFERROR(INDEX($F$8:$O$8,MATCH(F$12-$G$10,$F$6:$O$6,0)),0) -> 0 | G13: =IFERROR(INDEX($F$8:$O$8,MATCH(G$12-$G$10,$F$6:$O$6,0)),0) -> 0 | H13: =IFERROR(INDEX($F$8:$O$8,MATCH(H$12-$G$10,$F$6:$O$6,0)),0) -> 0 | I13: =IFERROR(INDEX($F$8:$O$8,MATCH(I$12-$G$10,$F$6:$O$6,0)),0) -> 0 | J13: =IFERROR(INDEX($F$8:$O$8,MATCH(J$12-$G$10,$F$6:$O$6,0)),0) -> 0 | K13: =IFERROR(INDEX($F$8:$O$8,MATCH(K$12-$G$10,$F$6:$O$6,0)),0) -> 0.10516068 | L13: =IFERROR(INDEX($F$8:$O$8,MATCH(L$12-$G$10,$F$6:$O$6,0)),0) -> 0.25365893 | M13: =IFERROR(INDEX($F$8:$O$8,MATCH(M$12-$G$10,$F$6:$O$6,0)),0) -> 0.27330095 | ... Z13: =IFERROR(INDEX($F$8:$O$8,MATCH(Z$12-$G$10,$F$6:$O$6,0)),0) -> 0
E15: Initial stock of homes: | G15: 100 | I15: Decadal growth rate of stock: | L15: 0.05
G34: Hummus Town House Demolitions, Using Candy Town Lifespan Distribution | AF34: Hummus Town House Stock, Using Candy Town Lifespan Distribution
B35: Stock | D35: Houses Built | G35: Year House Demolished & Rebuilt | AF35: Year House in Stock
B36: Total | C36: Change | D36: Cumulative | E36: Annual | F36: Year Built | G36: 2080 | H36: 2090 | I36: 2100 | J36: 2110 | K36: 2120 | L36: 2130 | M36: 2140 | N36: 2150 | O36: 2160 | P36: 2170 | Q36: 2180 | R36: 2190 | S36: 2200 | T36: 2210 | U36: 2220 | V36: 2230 | W36: 2240 | X36: 2250 | Y36: 2260 | Z36: 2270 | AA36: 2280 | AD36: # Built | AE36: Year Built | AF36: 2080 | AG36: 2090 | AH36: 2100 | AI36: 2110 | AJ36: 2120 | AK36: 2130 | AL36: 2140 | AM36: 2150 | AN36: 2160 | AO36: 2170 | AP36: 2180 | AQ36: 2190 | AR36: 2200 | AS36: 2210 | AT36: 2220 | AU36: 2230 | AV36: 2240 | AW36: 2250 | AX36: 2260 | AY36: 2270 | AZ36: 2280
B37: =G15 -> 100 | C37: 0 | D37: =E37 -> 100 | E37: =$G$15 -> 100 | F37: 2080 | G37: =IF(G$36>=$F37,$E37*INDEX($F$8:$Z$8,MATCH(G$67-$F37,$F$6:$Z$6,0)),0) -> 0 | H37: =IF(H$36>=$F37,$E37*INDEX($F$8:$Z$8,MATCH(H$67-$F37,$F$6:$Z$6,0)),0) -> 0 | I37: =IF(I$36>=$F37,$E37*INDEX($F$8:$Z$8,MATCH(I$67-$F37,$F$6:$Z$6,0)),0) -> 10.516068 | J37: =IF(J$36>=$F37,$E37*INDEX($F$8:$Z$8,MATCH(J$67-$F37,$F$6:$Z$6,0)),0) -> 25.365893 | K37: =IF(K$36>=$F37,$E37*INDEX($F$8:$Z$8,MATCH(K$67-$F37,$F$6:$Z$6,0)),0) -> 27.330095 | L37: =IF(L$36>=$F37,$E37*INDEX($F$8:$Z$8,MATCH(L$67-$F37,$F$6:$Z$6,0)),0) -> 19.886613 | M37: =IF(M$36>=$F37,$E37*INDEX($F$8:$Z$8,MATCH(M$67-$F37,$F$6:$Z$6,0)),0) -> 10.683679 | N37: =IF(N$36>=$F37,$E37*INDEX($F$8:$Z$8,MATCH(N$67-$F37,$F$6:$Z$6,0)),0) -> 4.3860885 | ... AA37: =IF(AA$36>=$F37,$E37*INDEX($F$8:$Z$8,MATCH(AA$67-$F37,$F$6:$Z$6,0)),0) -> 0 | AD37: {=E37:E57} -> 100 | AE37: 2080 | AF37: =IF(G$36>=$F37,$AD37-SUM($G37:G37),0) -> 100 | AG37: =IF(H$36>=$F37,$AD37-SUM($G37:H37),0) -> 100 | AH37: =IF(I$36>=$F37,$AD37-SUM($G37:I37),0) -> 89.483932 | AI37: =IF(J$36>=$F37,$AD37-SUM($G37:J37),0) -> 64.118039 | AJ37: =IF(K$36>=$F37,$AD37-SUM($G37:K37),0) -> 36.787944 | AK37: =IF(L$36>=$F37,$AD37-SUM($G37:L37),0) -> 16.901332 | AL37: =IF(M$36>=$F37,$AD37-SUM($G37:M37),0) -> 6.2176524 | AM37: =IF(N$36>=$F37,$AD37-SUM($G37:N37),0) -> 1.8315639 | ... AZ37: =IF(AA$36>=$F37,$AD37-SUM($G37:AA37),0) -> 1.4210855e-14
B38: =B37*(1+$L$15) -> 105 | C38: =B38-B37 -> 5 | D38: =D37+E38 -> 105 | E38: {=INDEX($G$58:$AA$58, 0, MATCH(F38,$G$36:$AA$36,0))+C38} -> 5 | F38: 2090 | G38: =IF(G$36>=$F38,$E38*INDEX($F$8:$Z$8,MATCH(G$67-$F38,$F$6:$Z$6,0)),0) -> 0 | H38: =IF(H$36>=$F38,$E38*INDEX($F$8:$Z$8,MATCH(H$67-$F38,$F$6:$Z$6,0)),0) -> 0 | I38: =IF(I$36>=$F38,$E38*INDEX($F$8:$Z$8,MATCH(I$67-$F38,$F$6:$Z$6,0)),0) -> 0 | J38: =IF(J$36>=$F38,$E38*INDEX($F$8:$Z$8,MATCH(J$67-$F38,$F$6:$Z$6,0)),0) -> 0.57523517 | K38: =IF(K$36>=$F38,$E38*INDEX($F$8:$Z$8,MATCH(K$67-$F38,$F$6:$Z$6,0)),0) -> 1.2892451 | L38: =IF(L$36>=$F38,$E38*INDEX($F$8:$Z$8,MATCH(L$67-$F38,$F$6:$Z$6,0)),0) -> 1.3561691 | M38: =IF(M$36>=$F38,$E38*INDEX($F$8:$Z$8,MATCH(M$67-$F38,$F$6:$Z$6,0)),0) -> 0.97051663 | N38: =IF(N$36>=$F38,$E38*INDEX($F$8:$Z$8,MATCH(N$67-$F38,$F$6:$Z$6,0)),0) -> 0.51403439 | ... AA38: =IF(AA$36>=$F38,$E38*INDEX($F$8:$Z$8,MATCH(AA$67-$F38,$F$6:$Z$6,0)),0) -> 0 | AD38: 5 | AE38: 2090 | AF38: =IF(G$36>=$F38,$AD38-SUM($G38:G38),0) -> 0 | AG38: =IF(H$36>=$F38,$AD38-SUM($G38:H38),0) -> 5 | AH38: =IF(I$36>=$F38,$AD38-SUM($G38:I38),0) -> 5 | AI38: =IF(J$36>=$F38,$AD38-SUM($G38:J38),0) -> 4.4247648 | AJ38: =IF(K$36>=$F38,$AD38-SUM($G38:K38),0) -> 3.1355198 | AK38: =IF(L$36>=$F38,$AD38-SUM($G38:L38),0) -> 1.7793507 | AL38: =IF(M$36>=$F38,$AD38-SUM($G38:M38),0) -> 0.80883405 | AM38: =IF(N$36>=$F38,$AD38-SUM($G38:N38),0) -> 0.29479966 | ... AZ38: =IF(AA$36>=$F38,$AD38-SUM($G38:AA38),0) -> 0.00088668249
B39: =B38*(1+$L$15) -> 110.25 | C39: =B39-B38 -> 5.25 | D39: =D38+E39 -> 121.7547 | E39: {=INDEX($G$58:$AA$58, 0, MATCH(F39,$G$36:$AA$36,0))+C39} -> 16.754703 | F39: 2100 | G39: =IF(G$36>=$F39,$E39*INDEX($F$8:$Z$8,MATCH(G$67-$F39,$F$6:$Z$6,0)),0) -> 0 | H39: =IF(H$36>=$F39,$E39*INDEX($F$8:$Z$8,MATCH(H$67-$F39,$F$6:$Z$6,0)),0) -> 0 | I39: =IF(I$36>=$F39,$E39*INDEX($F$8:$Z$8,MATCH(I$67-$F39,$F$6:$Z$6,0)),0) -> 0 | J39: =IF(J$36>=$F39,$E39*INDEX($F$8:$Z$8,MATCH(J$67-$F39,$F$6:$Z$6,0)),0) -> 0 | K39: =IF(K$36>=$F39,$E39*INDEX($F$8:$Z$8,MATCH(K$67-$F39,$F$6:$Z$6,0)),0) -> 1.9275789 | L39: =IF(L$36>=$F39,$E39*INDEX($F$8:$Z$8,MATCH(L$67-$F39,$F$6:$Z$6,0)),0) -> 4.3201837 | M39: =IF(M$36>=$F39,$E39*INDEX($F$8:$Z$8,MATCH(M$67-$F39,$F$6:$Z$6,0)),0) -> 4.5444421 | N39: =IF(N$36>=$F39,$E39*INDEX($F$8:$Z$8,MATCH(N$67-$F39,$F$6:$Z$6,0)),0) -> 3.2521437 | ... AA39: =IF(AA$36>=$F39,$E39*INDEX($F$8:$Z$8,MATCH(AA$67-$F39,$F$6:$Z$6,0)),0) -> 0 | AD39: 16.754703 | AE39: 2100 | AF39: =IF(G$36>=$F39,$AD39-SUM($G39:G39),0) -> 0 | AG39: =IF(H$36>=$F39,$AD39-SUM($G39:H39),0) -> 0 | AH39: =IF(I$36>=$F39,$AD39-SUM($G39:I39),0) -> 16.754703 | AI39: =IF(J$36>=$F39,$AD39-SUM($G39:J39),0) -> 16.754703 | AJ39: =IF(K$36>=$F39,$AD39-SUM($G39:K39),0) -> 14.827124 | AK39: =IF(L$36>=$F39,$AD39-SUM($G39:L39),0) -> 10.506941 | AL39: =IF(M$36>=$F39,$AD39-SUM($G39:M39),0) -> 5.9624986 | AM39: =IF(N$36>=$F39,$AD39-SUM($G39:N39),0) -> 2.7103549 | ... AZ39: =IF(AA$36>=$F39,$AD39-SUM($G39:AA39),0) -> 0.0029712204
B40: =B39*(1+$L$15) -> 115.7625 | C40: =B40-B39 -> 5.5125 | D40: =D39+E40 -> 153.62734 | E40: {=INDEX($G$58:$AA$58, 0, MATCH(F40,$G$36:$AA$36,0))+C40} -> 31.872636 | F40: 2110 | G40: =IF(G$36>=$F40,$E40*INDEX($F$8:$Z$8,MATCH(G$67-$F40,$F$6:$Z$6,0)),0) -> 0 | H40: =IF(H$36>=$F40,$E40*INDEX($F$8:$Z$8,MATCH(H$67-$F40,$F$6:$Z$6,0)),0) -> 0 | I40: =IF(I$36>=$F40,$E40*INDEX($F$8:$Z$8,MATCH(I$67-$F40,$F$6:$Z$6,0)),0) -> 0 | J40: =IF(J$36>=$F40,$E40*INDEX($F$8:$Z$8,MATCH(J$67-$F40,$F$6:$Z$6,0)),0) -> 0 | K40: =IF(K$36>=$F40,$E40*INDEX($F$8:$Z$8,MATCH(K$67-$F40,$F$6:$Z$6,0)),0) -> 0 | L40: =IF(L$36>=$F40,$E40*INDEX($F$8:$Z$8,MATCH(L$67-$F40,$F$6:$Z$6,0)),0) -> 3.6668523 | M40: =IF(M$36>=$F40,$E40*INDEX($F$8:$Z$8,MATCH(M$67-$F40,$F$6:$Z$6,0)),0) -> 8.2183278 | N40: =IF(N$36>=$F40,$E40*INDEX($F$8:$Z$8,MATCH(N$67-$F40,$F$6:$Z$6,0)),0) -> 8.6449368 | ... AA40: =IF(AA$36>=$F40,$E40*INDEX($F$8:$Z$8,MATCH(AA$67-$F40,$F$6:$Z$6,0)),0) -> 0 | AD40: 31.872636 | AE40: 2110 | AF40: =IF(G$36>=$F40,$AD40-SUM($G40:G40),0) -> 0 | AG40: =IF(H$36>=$F40,$AD40-SUM($G40:H40),0) -> 0 | AH40: =IF(I$36>=$F40,$AD40-SUM($G40:I40),0) -> 0 | AI40: =IF(J$36>=$F40,$AD40-SUM($G40:J40),0) -> 31.872636 | AJ40: =IF(K$36>=$F40,$AD40-SUM($G40:K40),0) -> 31.872636 | AK40: =IF(L$36>=$F40,$AD40-SUM($G40:L40),0) -> 28.205784 | AL40: =IF(M$36>=$F40,$AD40-SUM($G40:M40),0) -> 19.987456 | AM40: =IF(N$36>=$F40,$AD40-SUM($G40:N40),0) -> 11.342519 | ... AZ40: =IF(AA$36>=$F40,$AD40-SUM($G40:AA40),0) -> 0.0056521817
B41: =B40*(1+$L$15) -> 121.55063 | C41: =B41-B40 -> 5.788125 | D41: =D40+E41 -> 189.75567 | E41: {=INDEX($G$58:$AA$58, 0, MATCH(F41,$G$36:$AA$36,0))+C41} -> 36.128331 | F41: 2120 | G41: =IF(G$36>=$F41,$E41*INDEX($F$8:$Z$8,MATCH(G$67-$F41,$F$6:$Z$6,0)),0) -> 0 | H41: =IF(H$36>=$F41,$E41*INDEX($F$8:$Z$8,MATCH(H$67-$F41,$F$6:$Z$6,0)),0) -> 0 | I41: =IF(I$36>=$F41,$E41*INDEX($F$8:$Z$8,MATCH(I$67-$F41,$F$6:$Z$6,0)),0) -> 0 | J41: =IF(J$36>=$F41,$E41*INDEX($F$8:$Z$8,MATCH(J$67-$F41,$F$6:$Z$6,0)),0) -> 0 | K41: =IF(K$36>=$F41,$E41*INDEX($F$8:$Z$8,MATCH(K$67-$F41,$F$6:$Z$6,0)),0) -> 0 | L41: =IF(L$36>=$F41,$E41*INDEX($F$8:$Z$8,MATCH(L$67-$F41,$F$6:$Z$6,0)),0) -> 0 | M41: =IF(M$36>=$F41,$E41*INDEX($F$8:$Z$8,MATCH(M$67-$F41,$F$6:$Z$6,0)),0) -> 4.1564573 | N41: =IF(N$36>=$F41,$E41*INDEX($F$8:$Z$8,MATCH(N$67-$F41,$F$6:$Z$6,0)),0) -> 9.3156544 | ... AA41: =IF(AA$36>=$F41,$E41*INDEX($F$8:$Z$8,MATCH(AA$67-$F41,$F$6:$Z$6,0)),0) -> 0 | AD41: 36.128331 | AE41: 2120 | AF41: =IF(G$36>=$F41,$AD41-SUM($G41:G41),0) -> 0 | AG41: =IF(H$36>=$F41,$AD41-SUM($G41:H41),0) -> 0 | AH41: =IF(I$36>=$F41,$AD41-SUM($G41:I41),0) -> 0 | AI41: =IF(J$36>=$F41,$AD41-SUM($G41:J41),0) -> 0 | AJ41: =IF(K$36>=$F41,$AD41-SUM($G41:K41),0) -> 36.128331 | AK41: =IF(L$36>=$F41,$AD41-SUM($G41:L41),0) -> 36.128331 | AL41: =IF(M$36>=$F41,$AD41-SUM($G41:M41),0) -> 31.971873 | AM41: =IF(N$36>=$F41,$AD41-SUM($G41:N41),0) -> 22.656219 | ... AZ41: =IF(AA$36>=$F41,$AD41-SUM($G41:AA41),0) -> 0.0064068717
B42: =B41*(1+$L$15) -> 127.62816 | C42: =B42-B41 -> 6.0775313 | D42: =D41+E42 -> 224.58674 | E42: {=INDEX($G$58:$AA$58, 0, MATCH(F42,$G$36:$AA$36,0))+C42} -> 34.831069 | F42: 2130 | G42: =IF(G$36>=$F42,$E42*INDEX($F$8:$Z$8,MATCH(G$67-$F42,$F$6:$Z$6,0)),0) -> 0 | H42: =IF(H$36>=$F42,$E42*INDEX($F$8:$Z$8,MATCH(H$67-$F42,$F$6:$Z$6,0)),0) -> 0 | I42: =IF(I$36>=$F42,$E42*INDEX($F$8:$Z$8,MATCH(I$67-$F42,$F$6:$Z$6,0)),0) -> 0 | J42: =IF(J$36>=$F42,$E42*INDEX($F$8:$Z$8,MATCH(J$67-$F42,$F$6:$Z$6,0)),0) -> 0 | K42: =IF(K$36>=$F42,$E42*INDEX($F$8:$Z$8,MATCH(K$67-$F42,$F$6:$Z$6,0)),0) -> 0 | L42: =IF(L$36>=$F42,$E42*INDEX($F$8:$Z$8,MATCH(L$67-$F42,$F$6:$Z$6,0)),0) -> 0 | M42: =IF(M$36>=$F42,$E42*INDEX($F$8:$Z$8,MATCH(M$67-$F42,$F$6:$Z$6,0)),0) -> 0 | N42: =IF(N$36>=$F42,$E42*INDEX($F$8:$Z$8,MATCH(N$67-$F42,$F$6:$Z$6,0)),0) -> 4.0072112 | ... AA42: =IF(AA$36>=$F42,$E42*INDEX($F$8:$Z$8,MATCH(AA$67-$F42,$F$6:$Z$6,0)),0) -> 0 | AD42: 34.831069 | AE42: 2130 | AF42: =IF(G$36>=$F42,$AD42-SUM($G42:G42),0) -> 0 | AG42: =IF(H$36>=$F42,$AD42-SUM($G42:H42),0) -> 0 | AH42: =IF(I$36>=$F42,$AD42-SUM($G42:I42),0) -> 0 | AI42: =IF(J$36>=$F42,$AD42-SUM($G42:J42),0) -> 0 | AJ42: =IF(K$36>=$F42,$AD42-SUM($G42:K42),0) -> 0 | AK42: =IF(L$36>=$F42,$AD42-SUM($G42:L42),0) -> 34.831069 | AL42: =IF(M$36>=$F42,$AD42-SUM($G42:M42),0) -> 34.831069 | AM42: =IF(N$36>=$F42,$AD42-SUM($G42:N42),0) -> 30.823858 | ... AZ42: =IF(AA$36>=$F42,$AD42-SUM($G42:AA42),0) -> 0.0061768198
B43: =B42*(1+$L$15) -> 134.00956 | C43: =B43-B42 -> 6.3814078 | D43: =D42+E43 -> 259.13858 | E43: {=INDEX($G$58:$AA$58, 0, MATCH(F43,$G$36:$AA$36,0))+C43} -> 34.55184 | F43: 2140 | G43: =IF(G$36>=$F43,$E43*INDEX($F$8:$Z$8,MATCH(G$67-$F43,$F$6:$Z$6,0)),0) -> 0 | H43: =IF(H$36>=$F43,$E43*INDEX($F$8:$Z$8,MATCH(H$67-$F43,$F$6:$Z$6,0)),0) -> 0 | I43: =IF(I$36>=$F43,$E43*INDEX($F$8:$Z$8,MATCH(I$67-$F43,$F$6:$Z$6,0)),0) -> 0 | J43: =IF(J$36>=$F43,$E43*INDEX($F$8:$Z$8,MATCH(J$67-$F43,$F$6:$Z$6,0)),0) -> 0 | K43: =IF(K$36>=$F43,$E43*INDEX($F$8:$Z$8,MATCH(K$67-$F43,$F$6:$Z$6,0)),0) -> 0 | L43: =IF(L$36>=$F43,$E43*INDEX($F$8:$Z$8,MATCH(L$67-$F43,$F$6:$Z$6,0)),0) -> 0 | M43: =IF(M$36>=$F43,$E43*INDEX($F$8:$Z$8,MATCH(M$67-$F43,$F$6:$Z$6,0)),0) -> 0 | N43: =IF(N$36>=$F43,$E43*INDEX($F$8:$Z$8,MATCH(N$67-$F43,$F$6:$Z$6,0)),0) -> 0 | ... AA43: =IF(AA$36>=$F43,$E43*INDEX($F$8:$Z$8,MATCH(AA$67-$F43,$F$6:$Z$6,0)),0) -> 0 | AD43: 34.55184 | AE43: 2140 | AF43: =IF(G$36>=$F43,$AD43-SUM($G43:G43),0) -> 0 | AG43: =IF(H$36>=$F43,$AD43-SUM($G43:H43),0) -> 0 | AH43: =IF(I$36>=$F43,$AD43-SUM($G43:I43),0) -> 0 | AI43: =IF(J$36>=$F43,$AD43-SUM($G43:J43),0) -> 0 | AJ43: =IF(K$36>=$F43,$AD43-SUM($G43:K43),0) -> 0 | AK43: =IF(L$36>=$F43,$AD43-SUM($G43:L43),0) -> 0 | AL43: =IF(M$36>=$F43,$AD43-SUM($G43:M43),0) -> 34.55184 | AM43: =IF(N$36>=$F43,$AD43-SUM($G43:N43),0) -> 34.55184 | ... AZ43: =IF(AA$36>=$F43,$AD43-SUM($G43:AA43),0) -> 0.0061273022
B44: =B43*(1+$L$15) -> 140.71004 | C44: =B44-B43 -> 6.7004782 | D44: =D43+E44 -> 295.73868 | E44: {=INDEX($G$58:$AA$58, 0, MATCH(F44,$G$36:$AA$36,0))+C44} -> 36.600098 | F44: 2150 | G44: =IF(G$36>=$F44,$E44*INDEX($F$8:$Z$8,MATCH(G$67-$F44,$F$6:$Z$6,0)),0) -> 0 | H44: =IF(H$36>=$F44,$E44*INDEX($F$8:$Z$8,MATCH(H$67-$F44,$F$6:$Z$6,0)),0) -> 0 | I44: =IF(I$36>=$F44,$E44*INDEX($F$8:$Z$8,MATCH(I$67-$F44,$F$6:$Z$6,0)),0) -> 0 | J44: =IF(J$36>=$F44,$E44*INDEX($F$8:$Z$8,MATCH(J$67-$F44,$F$6:$Z$6,0)),0) -> 0 | K44: =IF(K$36>=$F44,$E44*INDEX($F$8:$Z$8,MATCH(K$67-$F44,$F$6:$Z$6,0)),0) -> 0 | L44: =IF(L$36>=$F44,$E44*INDEX($F$8:$Z$8,MATCH(L$67-$F44,$F$6:$Z$6,0)),0) -> 0 | M44: =IF(M$36>=$F44,$E44*INDEX($F$8:$Z$8,MATCH(M$67-$F44,$F$6:$Z$6,0)),0) -> 0 | N44: =IF(N$36>=$F44,$E44*INDEX($F$8:$Z$8,MATCH(N$67-$F44,$F$6:$Z$6,0)),0) -> 0 | ... AA44: =IF(AA$36>=$F44,$E44*INDEX($F$8:$Z$8,MATCH(AA$67-$F44,$F$6:$Z$6,0)),0) -> 0 | AD44: 36.600098 | AE44: 2150 | AF44: =IF(G$36>=$F44,$AD44-SUM($G44:G44),0) -> 0 | AG44: =IF(H$36>=$F44,$AD44-SUM($G44:H44),0) -> 0 | AH44: =IF(I$36>=$F44,$AD44-SUM($G44:I44),0) -> 0 | AI44: =IF(J$36>=$F44,$AD44-SUM($G44:J44),0) -> 0 | AJ44: =IF(K$36>=$F44,$AD44-SUM($G44:K44),0) -> 0 | AK44: =IF(L$36>=$F44,$AD44-SUM($G44:L44),0) -> 0 | AL44: =IF(M$36>=$F44,$AD44-SUM($G44:M44),0) -> 0 | AM44: =IF(N$36>=$F44,$AD44-SUM($G44:N44),0) -> 36.600098 | ... AZ44: =IF(AA$36>=$F44,$AD44-SUM($G44:AA44),0) -> 0.0064905331
B45: =B44*(1+$L$15) -> 147.74554 | C45: =B45-B44 -> 7.0355021 | D45: =D44+E45 -> 334.95963 | E45: {=INDEX($G$58:$AA$58, 0, MATCH(F45,$G$36:$AA$36,0))+C45} -> 39.220957 | F45: 2160 | G45: =IF(G$36>=$F45,$E45*INDEX($F$8:$Z$8,MATCH(G$67-$F45,$F$6:$Z$6,0)),0) -> 0 | H45: =IF(H$36>=$F45,$E45*INDEX($F$8:$Z$8,MATCH(H$67-$F45,$F$6:$Z$6,0)),0) -> 0 | I45: =IF(I$36>=$F45,$E45*INDEX($F$8:$Z$8,MATCH(I$67-$F45,$F$6:$Z$6,0)),0) -> 0 | J45: =IF(J$36>=$F45,$E45*INDEX($F$8:$Z$8,MATCH(J$67-$F45,$F$6:$Z$6,0)),0) -> 0 | K45: =IF(K$36>=$F45,$E45*INDEX($F$8:$Z$8,MATCH(K$67-$F45,$F$6:$Z$6,0)),0) -> 0 | L45: =IF(L$36>=$F45,$E45*INDEX($F$8:$Z$8,MATCH(L$67-$F45,$F$6:$Z$6,0)),0) -> 0 | M45: =IF(M$36>=$F45,$E45*INDEX($F$8:$Z$8,MATCH(M$67-$F45,$F$6:$Z$6,0)),0) -> 0 | N45: =IF(N$36>=$F45,$E45*INDEX($F$8:$Z$8,MATCH(N$67-$F45,$F$6:$Z$6,0)),0) -> 0 | ... AA45: =IF(AA$36>=$F45,$E45*INDEX($F$8:$Z$8,MATCH(AA$67-$F45,$F$6:$Z$6,0)),0) -> 0 | AD45: 39.220957 | AE45: 2160 | AF45: =IF(G$36>=$F45,$AD45-SUM($G45:G45),0) -> 0 | AG45: =IF(H$36>=$F45,$AD45-SUM($G45:H45),0) -> 0 | AH45: =IF(I$36>=$F45,$AD45-SUM($G45:I45),0) -> 0 | AI45: =IF(J$36>=$F45,$AD45-SUM($G45:J45),0) -> 0 | AJ45: =IF(K$36>=$F45,$AD45-SUM($G45:K45),0) -> 0 | AK45: =IF(L$36>=$F45,$AD45-SUM($G45:L45),0) -> 0 | AL45: =IF(M$36>=$F45,$AD45-SUM($G45:M45),0) -> 0 | AM45: =IF(N$36>=$F45,$AD45-SUM($G45:N45),0) -> 0 | ... AZ45: =IF(AA$36>=$F45,$AD45-SUM($G45:AA45),0) -> 0.0069553071
B46: =B45*(1+$L$15) -> 155.13282 | C46: =B46-B45 -> 7.3872772 | D46: =D45+E46 -> 376.36709 | E46: {=INDEX($G$58:$AA$58, 0, MATCH(F46,$G$36:$AA$36,0))+C46} -> 41.407458 | F46: 2170 | G46: =IF(G$36>=$F46,$E46*INDEX($F$8:$Z$8,MATCH(G$67-$F46,$F$6:$Z$6,0)),0) -> 0 | H46: =IF(H$36>=$F46,$E46*INDEX($F$8:$Z$8,MATCH(H$67-$F46,$F$6:$Z$6,0)),0) -> 0 | I46: =IF(I$36>=$F46,$E46*INDEX($F$8:$Z$8,MATCH(I$67-$F46,$F$6:$Z$6,0)),0) -> 0 | J46: =IF(J$36>=$F46,$E46*INDEX($F$8:$Z$8,MATCH(J$67-$F46,$F$6:$Z$6,0)),0) -> 0 | K46: =IF(K$36>=$F46,$E46*INDEX($F$8:$Z$8,MATCH(K$67-$F46,$F$6:$Z$6,0)),0) -> 0 | L46: =IF(L$36>=$F46,$E46*INDEX($F$8:$Z$8,MATCH(L$67-$F46,$F$6:$Z$6,0)),0) -> 0 | M46: =IF(M$36>=$F46,$E46*INDEX($F$8:$Z$8,MATCH(M$67-$F46,$F$6:$Z$6,0)),0) -> 0 | N46: =IF(N$36>=$F46,$E46*INDEX($F$8:$Z$8,MATCH(N$67-$F46,$F$6:$Z$6,0)),0) -> 0 | ... AA46: =IF(AA$36>=$F46,$E46*INDEX($F$8:$Z$8,MATCH(AA$67-$F46,$F$6:$Z$6,0)),0) -> 0 | AD46: 41.407458 | AE46: 2170 | AF46: =IF(G$36>=$F46,$AD46-SUM($G46:G46),0) -> 0 | AG46: =IF(H$36>=$F46,$AD46-SUM($G46:H46),0) -> 0 | AH46: =IF(I$36>=$F46,$AD46-SUM($G46:I46),0) -> 0 | AI46: =IF(J$36>=$F46,$AD46-SUM($G46:J46),0) -> 0 | AJ46: =IF(K$36>=$F46,$AD46-SUM($G46:K46),0) -> 0 | AK46: =IF(L$36>=$F46,$AD46-SUM($G46:L46),0) -> 0 | AL46: =IF(M$36>=$F46,$AD46-SUM($G46:M46),0) -> 0 | AM46: =IF(N$36>=$F46,$AD46-SUM($G46:N46),0) -> 0 | ... AZ46: =IF(AA$36>=$F46,$AD46-SUM($G46:AA46),0) -> 0.0073430537
B47: =B46*(1+$L$15) -> 162.88946 | C47: =B47-B46 -> 7.7566411 | D47: =D46+E47 -> 419.48761 | E47: {=INDEX($G$58:$AA$58, 0, MATCH(F47,$G$36:$AA$36,0))+C47} -> 43.120514 | F47: 2180 | G47: =IF(G$36>=$F47,$E47*INDEX($F$8:$Z$8,MATCH(G$67-$F47,$F$6:$Z$6,0)),0) -> 0 | H47: =IF(H$36>=$F47,$E47*INDEX($F$8:$Z$8,MATCH(H$67-$F47,$F$6:$Z$6,0)),0) -> 0 | I47: =IF(I$36>=$F47,$E47*INDEX($F$8:$Z$8,MATCH(I$67-$F47,$F$6:$Z$6,0)),0) -> 0 | J47: =IF(J$36>=$F47,$E47*INDEX($F$8:$Z$8,MATCH(J$67-$F47,$F$6:$Z$6,0)),0) -> 0 | K47: =IF(K$36>=$F47,$E47*INDEX($F$8:$Z$8,MATCH(K$67-$F47,$F$6:$Z$6,0)),0) -> 0 | L47: =IF(L$36>=$F47,$E47*INDEX($F$8:$Z$8,MATCH(L$67-$F47,$F$6:$Z$6,0)),0) -> 0 | M47: =IF(M$36>=$F47,$E47*INDEX($F$8:$Z$8,MATCH(M$67-$F47,$F$6:$Z$6,0)),0) -> 0 | N47: =IF(N$36>=$F47,$E47*INDEX($F$8:$Z$8,MATCH(N$67-$F47,$F$6:$Z$6,0)),0) -> 0 | ... AA47: =IF(AA$36>=$F47,$E47*INDEX($F$8:$Z$8,MATCH(AA$67-$F47,$F$6:$Z$6,0)),0) -> 0 | AD47: 43.120514 | AE47: 2180 | AF47: =IF(G$36>=$F47,$AD47-SUM($G47:G47),0) -> 0 | AG47: =IF(H$36>=$F47,$AD47-SUM($G47:H47),0) -> 0 | AH47: =IF(I$36>=$F47,$AD47-SUM($G47:I47),0) -> 0 | AI47: =IF(J$36>=$F47,$AD47-SUM($G47:J47),0) -> 0 | AJ47: =IF(K$36>=$F47,$AD47-SUM($G47:K47),0) -> 0 | AK47: =IF(L$36>=$F47,$AD47-SUM($G47:L47),0) -> 0 | AL47: =IF(M$36>=$F47,$AD47-SUM($G47:M47),0) -> 0 | AM47: =IF(N$36>=$F47,$AD47-SUM($G47:N47),0) -> 0 | ... AZ47: =IF(AA$36>=$F47,$AD47-SUM($G47:AA47),0) -> 0.007646841
B48: =B47*(1+$L$15) -> 171.03394 | C48: =B48-B47 -> 8.1444731 | D48: =D47+E48 -> 464.71401 | E48: {=INDEX($G$58:$AA$58, 0, MATCH(F48,$G$36:$AA$36,0))+C48} -> 45.226409 | F48: 2190 | G48: =IF(G$36>=$F48,$E48*INDEX($F$8:$Z$8,MATCH(G$67-$F48,$F$6:$Z$6,0)),0) -> 0 | H48: =IF(H$36>=$F48,$E48*INDEX($F$8:$Z$8,MATCH(H$67-$F48,$F$6:$Z$6,0)),0) -> 0 | I48: =IF(I$36>=$F48,$E48*INDEX($F$8:$Z$8,MATCH(I$67-$F48,$F$6:$Z$6,0)),0) -> 0 | J48: =IF(J$36>=$F48,$E48*INDEX($F$8:$Z$8,MATCH(J$67-$F48,$F$6:$Z$6,0)),0) -> 0 | K48: =IF(K$36>=$F48,$E48*INDEX($F$8:$Z$8,MATCH(K$67-$F48,$F$6:$Z$6,0)),0) -> 0 | L48: =IF(L$36>=$F48,$E48*INDEX($F$8:$Z$8,MATCH(L$67-$F48,$F$6:$Z$6,0)),0) -> 0 | M48: =IF(M$36>=$F48,$E48*INDEX($F$8:$Z$8,MATCH(M$67-$F48,$F$6:$Z$6,0)),0) -> 0 | N48: =IF(N$36>=$F48,$E48*INDEX($F$8:$Z$8,MATCH(N$67-$F48,$F$6:$Z$6,0)),0) -> 0 | ... AA48: =IF(AA$36>=$F48,$E48*INDEX($F$8:$Z$8,MATCH(AA$67-$F48,$F$6:$Z$6,0)),0) -> 0.18090564 | AD48: 45.226409 | AE48: 2190 | AF48: =IF(G$36>=$F48,$AD48-SUM($G48:G48),0) -> 0 | AG48: =IF(H$36>=$F48,$AD48-SUM($G48:H48),0) -> 0 | AH48: =IF(I$36>=$F48,$AD48-SUM($G48:I48),0) -> 0 | AI48: =IF(J$36>=$F48,$AD48-SUM($G48:J48),0) -> 0 | AJ48: =IF(K$36>=$F48,$AD48-SUM($G48:K48),0) -> 0 | AK48: =IF(L$36>=$F48,$AD48-SUM($G48:L48),0) -> 0 | AL48: =IF(M$36>=$F48,$AD48-SUM($G48:M48),0) -> 0 | AM48: =IF(N$36>=$F48,$AD48-SUM($G48:N48),0) -> 0 | ... AZ48: =IF(AA$36>=$F48,$AD48-SUM($G48:AA48),0) -> 0.0080202931
B49: =B48*(1+$L$15) -> 179.58563 | C49: =B49-B48 -> 8.5516968 | D49: =D48+E49 -> 512.25054 | E49: {=INDEX($G$58:$AA$58, 0, MATCH(F49,$G$36:$AA$36,0))+C49} -> 47.536528 | F49: 2200 | G49: =IF(G$36>=$F49,$E49*INDEX($F$8:$Z$8,MATCH(G$67-$F49,$F$6:$Z$6,0)),0) -> 0 | H49: =IF(H$36>=$F49,$E49*INDEX($F$8:$Z$8,MATCH(H$67-$F49,$F$6:$Z$6,0)),0) -> 0 | I49: =IF(I$36>=$F49,$E49*INDEX($F$8:$Z$8,MATCH(I$67-$F49,$F$6:$Z$6,0)),0) -> 0 | J49: =IF(J$36>=$F49,$E49*INDEX($F$8:$Z$8,MATCH(J$67-$F49,$F$6:$Z$6,0)),0) -> 0 | K49: =IF(K$36>=$F49,$E49*INDEX($F$8:$Z$8,MATCH(K$67-$F49,$F$6:$Z$6,0)),0) -> 0 | L49: =IF(L$36>=$F49,$E49*INDEX($F$8:$Z$8,MATCH(L$67-$F49,$F$6:$Z$6,0)),0) -> 0 | M49: =IF(M$36>=$F49,$E49*INDEX($F$8:$Z$8,MATCH(M$67-$F49,$F$6:$Z$6,0)),0) -> 0 | N49: =IF(N$36>=$F49,$E49*INDEX($F$8:$Z$8,MATCH(N$67-$F49,$F$6:$Z$6,0)),0) -> 0 | ... AA49: =IF(AA$36>=$F49,$E49*INDEX($F$8:$Z$8,MATCH(AA$67-$F49,$F$6:$Z$6,0)),0) -> 0.62397425 | AD49: 47.536528 | AE49: 2200 | AF49: =IF(G$36>=$F49,$AD49-SUM($G49:G49),0) -> 0 | AG49: =IF(H$36>=$F49,$AD49-SUM($G49:H49),0) -> 0 | AH49: =IF(I$36>=$F49,$AD49-SUM($G49:I49),0) -> 0 | AI49: =IF(J$36>=$F49,$AD49-SUM($G49:J49),0) -> 0 | AJ49: =IF(K$36>=$F49,$AD49-SUM($G49:K49),0) -> 0 | AK49: =IF(L$36>=$F49,$AD49-SUM($G49:L49),0) -> 0 | AL49: =IF(M$36>=$F49,$AD49-SUM($G49:M49),0) -> 0 | AM49: =IF(N$36>=$F49,$AD49-SUM($G49:N49),0) -> 0 | ... AZ49: =IF(AA$36>=$F49,$AD49-SUM($G49:AA49),0) -> 0.19857608
... B57: =B56*(1+$L$15) -> 265.32977 | C57: =B57-B56 -> 12.634751 | D57: =D56+E57 -> 989.07025 | E57: {=INDEX($G$58:$AA$58, 0, MATCH(F57,$G$36:$AA$36,0))+C57} -> 70.254368 | F57: 2280 | G57: =IF(G$36>=$F57,$E57*INDEX($F$8:$Z$8,MATCH(G$67-$F57,$F$6:$Z$6,0)),0) -> 0 | H57: =IF(H$36>=$F57,$E57*INDEX($F$8:$Z$8,MATCH(H$67-$F57,$F$6:$Z$6,0)),0) -> 0 | I57: =IF(I$36>=$F57,$E57*INDEX($F$8:$Z$8,MATCH(I$67-$F57,$F$6:$Z$6,0)),0) -> 0 | J57: =IF(J$36>=$F57,$E57*INDEX($F$8:$Z$8,MATCH(J$67-$F57,$F$6:$Z$6,0)),0) -> 0 | K57: =IF(K$36>=$F57,$E57*INDEX($F$8:$Z$8,MATCH(K$67-$F57,$F$6:$Z$6,0)),0) -> 0 | L57: =IF(L$36>=$F57,$E57*INDEX($F$8:$Z$8,MATCH(L$67-$F57,$F$6:$Z$6,0)),0) -> 0 | M57: =IF(M$36>=$F57,$E57*INDEX($F$8:$Z$8,MATCH(M$67-$F57,$F$6:$Z$6,0)),0) -> 0 | N57: =IF(N$36>=$F57,$E57*INDEX($F$8:$Z$8,MATCH(N$67-$F57,$F$6:$Z$6,0)),0) -> 0 | ... AA57: =IF(AA$36>=$F57,$E57*INDEX($F$8:$Z$8,MATCH(AA$67-$F57,$F$6:$Z$6,0)),0) -> 0 | AD57: 70.254368 | AE57: 2280 | AF57: =IF(G$36>=$F57,$AD57-SUM($G57:G57),0) -> 0 | AG57: =IF(H$36>=$F57,$AD57-SUM($G57:H57),0) -> 0 | AH57: =IF(I$36>=$F57,$AD57-SUM($G57:I57),0) -> 0 | AI57: =IF(J$36>=$F57,$AD57-SUM($G57:J57),0) -> 0 | AJ57: =IF(K$36>=$F57,$AD57-SUM($G57:K57),0) -> 0 | AK57: =IF(L$36>=$F57,$AD57-SUM($G57:L57),0) -> 0 | AL57: =IF(M$36>=$F57,$AD57-SUM($G57:M57),0) -> 0 | AM57: =IF(N$36>=$F57,$AD57-SUM($G57:N57),0) -> 0 | ... AZ57: =IF(AA$36>=$F57,$AD57-SUM($G57:AA57),0) -> 70.254368
E58: =SUM(E36:E57) -> 989.07025 | F58: TOTAL | G58: =SUM(G37:G57) -> 0 | H58: =SUM(H37:H57) -> 0 | I58: =SUM(I37:I57) -> 11.504703 | J58: =SUM(J37:J57) -> 26.360136 | K58: =SUM(K37:K57) -> 30.340206 | L58: =SUM(L37:L57) -> 28.753538 | M58: =SUM(M37:M57) -> 28.170432 | N58: =SUM(N37:N57) -> 29.899619 | ... AA58: =SUM(AA37:AA57) -> 57.619617 | AD58: =SUM(AD36:AD57) -> 989.07025 | AE58: TOTAL | AF58: =SUM(AF37:AF57) -> 100 | AG58: =SUM(AG37:AG57) -> 105 | AH58: =SUM(AH37:AH57) -> 110.25 | AI58: =SUM(AI37:AI57) -> 115.7625 | AJ58: =SUM(AJ37:AJ57) -> 121.55063 | AK58: =SUM(AK37:AK57) -> 127.62816 | AL58: =SUM(AL37:AL57) -> 134.00956 | AM58: =SUM(AM37:AM57) -> 140.71004 | ... AZ58: =SUM(AZ37:AZ57) -> 265.32977
F59: Cumulative | G59: =G58 -> 0 | H59: =G59+H58 -> 0 | I59: =H59+I58 -> 11.504703 | J59: =I59+J58 -> 37.86484 | K59: =J59+K58 -> 68.205045 | L59: =K59+L58 -> 96.958583 | M59: =L59+M58 -> 125.12901 | N59: =M59+N58 -> 155.02863 | O59: =N59+O58 -> 187.21409 | ... AA59: =Z59+AA58 -> 723.74048
G65: Hummus Town House Demolitions, Using Hummus Town Lifespan Distribution | AF65: Hummus Town House Stock, Using Hummus Town Lifespan Distribution
B66: Not Built | D66: Houses Built | G66: Year House Demolished & Rebuilt | AF66: Year House in Stock
B67: Cumulative | C67: Annual | D67: Cumulative | E67: Annual | F67: Year Built | G67: 2080 | H67: 2090 | I67: 2100 | J67: 2110 | K67: 2120 | L67: 2130 | M67: 2140 | N67: 2150 | O67: 2160 | P67: 2170 | Q67: 2180 | R67: 2190 | S67: 2200 | T67: 2210 | U67: 2220 | V67: 2230 | W67: 2240 | X67: 2250 | Y67: 2260 | Z67: 2270 | AA67: 2280 | AD67: # Built | AE67: Year Built | AF67: 2080 | AG67: 2090 | AH67: 2100 | AI67: 2110 | AJ67: 2120 | AK67: 2130 | AL67: 2140 | AM67: 2150 | AN67: 2160 | AO67: 2170 | AP67: 2180 | AQ67: 2190 | AR67: 2200 | AS67: 2210 | AT67: 2220 | AU67: 2230 | AV67: 2240 | AW67: 2250 | AX67: 2260 | AY67: 2270 | AZ67: 2280
B68: =C68 -> 0 | C68: =E37-E68 -> 0 | D68: =E68 -> 100 | E68: =$G$15 -> 100 | F68: 2080 | G68: =IF(G$36>=$F68,$E68*INDEX($F$13:$Z$13,MATCH(G$67-$F68,$F$12:$Z$12,0)),0) -> 0 | H68: =IF(H$36>=$F68,$E68*INDEX($F$13:$Z$13,MATCH(H$67-$F68,$F$12:$Z$12,0)),0) -> 0 | I68: =IF(I$36>=$F68,$E68*INDEX($F$13:$Z$13,MATCH(I$67-$F68,$F$12:$Z$12,0)),0) -> 0 | J68: =IF(J$36>=$F68,$E68*INDEX($F$13:$Z$13,MATCH(J$67-$F68,$F$12:$Z$12,0)),0) -> 0 | K68: =IF(K$36>=$F68,$E68*INDEX($F$13:$Z$13,MATCH(K$67-$F68,$F$12:$Z$12,0)),0) -> 0 | L68: =IF(L$36>=$F68,$E68*INDEX($F$13:$Z$13,MATCH(L$67-$F68,$F$12:$Z$12,0)),0) -> 10.516068 | M68: =IF(M$36>=$F68,$E68*INDEX($F$13:$Z$13,MATCH(M$67-$F68,$F$12:$Z$12,0)),0) -> 25.365893 | N68: =IF(N$36>=$F68,$E68*INDEX($F$13:$Z$13,MATCH(N$67-$F68,$F$12:$Z$12,0)),0) -> 27.330095 | ... AA68: =IF(AA$36>=$F68,$E68*INDEX($F$13:$Z$13,MATCH(AA$67-$F68,$F$12:$Z$12,0)),0) -> 0 | AD68: {=E68:E88} -> 100 | AE68: 2080 | AF68: =IF(G$36>=$F68,$AD68-SUM($G68:G68),0) -> 100 | AG68: =IF(H$36>=$F68,$AD68-SUM($G68:H68),0) -> 100 | AH68: =IF(I$36>=$F68,$AD68-SUM($G68:I68),0) -> 100 | AI68: =IF(J$36>=$F68,$AD68-SUM($G68:J68),0) -> 100 | AJ68: =IF(K$36>=$F68,$AD68-SUM($G68:K68),0) -> 100 | AK68: =IF(L$36>=$F68,$AD68-SUM($G68:L68),0) -> 89.483932 | AL68: =IF(M$36>=$F68,$AD68-SUM($G68:M68),0) -> 64.118039 | AM68: =IF(N$36>=$F68,$AD68-SUM($G68:N68),0) -> 36.787944 | ... AZ68: =IF(AA$36>=$F68,$AD68-SUM($G68:AA68),0) -> 0.081598784
B69: =B68+C69 -> 0 | C69: =E38-E69 -> 0 | D69: =D68+E69 -> 105 | E69: {=INDEX($G$89:$AA$89, 0, MATCH(F69,$G$67:$AA$67,0))+C38} -> 5 | F69: 2090 | G69: =IF(G$36>=$F69,$E69*INDEX($F$13:$Z$13,MATCH(G$67-$F69,$F$12:$Z$12,0)),0) -> 0 | H69: =IF(H$36>=$F69,$E69*INDEX($F$13:$Z$13,MATCH(H$67-$F69,$F$12:$Z$12,0)),0) -> 0 | I69: =IF(I$36>=$F69,$E69*INDEX($F$13:$Z$13,MATCH(I$67-$F69,$F$12:$Z$12,0)),0) -> 0 | J69: =IF(J$36>=$F69,$E69*INDEX($F$13:$Z$13,MATCH(J$67-$F69,$F$12:$Z$12,0)),0) -> 0 | K69: =IF(K$36>=$F69,$E69*INDEX($F$13:$Z$13,MATCH(K$67-$F69,$F$12:$Z$12,0)),0) -> 0 | L69: =IF(L$36>=$F69,$E69*INDEX($F$13:$Z$13,MATCH(L$67-$F69,$F$12:$Z$12,0)),0) -> 0 | M69: =IF(M$36>=$F69,$E69*INDEX($F$13:$Z$13,MATCH(M$67-$F69,$F$12:$Z$12,0)),0) -> 0.57523517 | N69: =IF(N$36>=$F69,$E69*INDEX($F$13:$Z$13,MATCH(N$67-$F69,$F$12:$Z$12,0)),0) -> 1.2892451 | ... AA69: =IF(AA$36>=$F69,$E69*INDEX($F$13:$Z$13,MATCH(AA$67-$F69,$F$12:$Z$12,0)),0) -> 0 | AD69: 5 | AE69: 2090 | AF69: =IF(G$36>=$F69,$AD69-SUM($G69:G69),0) -> 0 | AG69: =IF(H$36>=$F69,$AD69-SUM($G69:H69),0) -> 5 | AH69: =IF(I$36>=$F69,$AD69-SUM($G69:I69),0) -> 5 | AI69: =IF(J$36>=$F69,$AD69-SUM($G69:J69),0) -> 5 | AJ69: =IF(K$36>=$F69,$AD69-SUM($G69:K69),0) -> 5 | AK69: =IF(L$36>=$F69,$AD69-SUM($G69:L69),0) -> 5 | AL69: =IF(M$36>=$F69,$AD69-SUM($G69:M69),0) -> 4.4247648 | AM69: =IF(N$36>=$F69,$AD69-SUM($G69:N69),0) -> 3.1355198 | ... AZ69: =IF(AA$36>=$F69,$AD69-SUM($G69:AA69),0) -> 0.00088668249
B70: =B69+C70 -> 11.504703 | C70: =E39-E70 -> 11.504703 | D70: =D69+E70 -> 110.25 | E70: {=INDEX($G$89:$AA$89, 0, MATCH(F70,$G$67:$AA$67,0))+C39} -> 5.25 | F70: 2100 | G70: =IF(G$36>=$F70,$E70*INDEX($F$13:$Z$13,MATCH(G$67-$F70,$F$12:$Z$12,0)),0) -> 0 | H70: =IF(H$36>=$F70,$E70*INDEX($F$13:$Z$13,MATCH(H$67-$F70,$F$12:$Z$12,0)),0) -> 0 | I70: =IF(I$36>=$F70,$E70*INDEX($F$13:$Z$13,MATCH(I$67-$F70,$F$12:$Z$12,0)),0) -> 0 | J70: =IF(J$36>=$F70,$E70*INDEX($F$13:$Z$13,MATCH(J$67-$F70,$F$12:$Z$12,0)),0) -> 0 | K70: =IF(K$36>=$F70,$E70*INDEX($F$13:$Z$13,MATCH(K$67-$F70,$F$12:$Z$12,0)),0) -> 0 | L70: =IF(L$36>=$F70,$E70*INDEX($F$13:$Z$13,MATCH(L$67-$F70,$F$12:$Z$12,0)),0) -> 0 | M70: =IF(M$36>=$F70,$E70*INDEX($F$13:$Z$13,MATCH(M$67-$F70,$F$12:$Z$12,0)),0) -> 0 | N70: =IF(N$36>=$F70,$E70*INDEX($F$13:$Z$13,MATCH(N$67-$F70,$F$12:$Z$12,0)),0) -> 0.60399693 | ... AA70: =IF(AA$36>=$F70,$E70*INDEX($F$13:$Z$13,MATCH(AA$67-$F70,$F$12:$Z$12,0)),0) -> 0 | AD70: 5.25 | AE70: 2100 | AF70: =IF(G$36>=$F70,$AD70-SUM($G70:G70),0) -> 0 | AG70: =IF(H$36>=$F70,$AD70-SUM($G70:H70),0) -> 0 | AH70: =IF(I$36>=$F70,$AD70-SUM($G70:I70),0) -> 5.25 | AI70: =IF(J$36>=$F70,$AD70-SUM($G70:J70),0) -> 5.25 | AJ70: =IF(K$36>=$F70,$AD70-SUM($G70:K70),0) -> 5.25 | AK70: =IF(L$36>=$F70,$AD70-SUM($G70:L70),0) -> 5.25 | AL70: =IF(M$36>=$F70,$AD70-SUM($G70:M70),0) -> 5.25 | AM70: =IF(N$36>=$F70,$AD70-SUM($G70:N70),0) -> 4.6460031 | ... AZ70: =IF(AA$36>=$F70,$AD70-SUM($G70:AA70),0) -> 0.00093101662
B71: =B70+C71 -> 37.86484 | C71: =E40-E71 -> 26.360136 | D71: =D70+E71 -> 115.7625 | E71: {=INDEX($G$89:$AA$89, 0, MATCH(F71,$G$67:$AA$67,0))+C40} -> 5.5125 | F71: 2110 | G71: =IF(G$36>=$F71,$E71*INDEX($F$13:$Z$13,MATCH(G$67-$F71,$F$12:$Z$12,0)),0) -> 0 | H71: =IF(H$36>=$F71,$E71*INDEX($F$13:$Z$13,MATCH(H$67-$F71,$F$12:$Z$12,0)),0) -> 0 | I71: =IF(I$36>=$F71,$E71*INDEX($F$13:$Z$13,MATCH(I$67-$F71,$F$12:$Z$12,0)),0) -> 0 | J71: =IF(J$36>=$F71,$E71*INDEX($F$13:$Z$13,MATCH(J$67-$F71,$F$12:$Z$12,0)),0) -> 0 | K71: =IF(K$36>=$F71,$E71*INDEX($F$13:$Z$13,MATCH(K$67-$F71,$F$12:$Z$12,0)),0) -> 0 | L71: =IF(L$36>=$F71,$E71*INDEX($F$13:$Z$13,MATCH(L$67-$F71,$F$12:$Z$12,0)),0) -> 0 | M71: =IF(M$36>=$F71,$E71*INDEX($F$13:$Z$13,MATCH(M$67-$F71,$F$12:$Z$12,0)),0) -> 0 | N71: =IF(N$36>=$F71,$E71*INDEX($F$13:$Z$13,MATCH(N$67-$F71,$F$12:$Z$12,0)),0) -> 0 | ... AA71: =IF(AA$36>=$F71,$E71*INDEX($F$13:$Z$13,MATCH(AA$67-$F71,$F$12:$Z$12,0)),0) -> 0 | AD71: 5.5125 | AE71: 2110 | AF71: =IF(G$36>=$F71,$AD71-SUM($G71:G71),0) -> 0 | AG71: =IF(H$36>=$F71,$AD71-SUM($G71:H71),0) -> 0 | AH71: =IF(I$36>=$F71,$AD71-SUM($G71:I71),0) -> 0 | AI71: =IF(J$36>=$F71,$AD71-SUM($G71:J71),0) -> 5.5125 | AJ71: =IF(K$36>=$F71,$AD71-SUM($G71:K71),0) -> 5.5125 | AK71: =IF(L$36>=$F71,$AD71-SUM($G71:L71),0) -> 5.5125 | AL71: =IF(M$36>=$F71,$AD71-SUM($G71:M71),0) -> 5.5125 | AM71: =IF(N$36>=$F71,$AD71-SUM($G71:N71),0) -> 5.5125 | ... AZ71: =IF(AA$36>=$F71,$AD71-SUM($G71:AA71),0) -> 0.00097756745
B72: =B71+C72 -> 68.205045 | C72: =E41-E72 -> 30.340206 | D72: =D71+E72 -> 121.55063 | E72: {=INDEX($G$89:$AA$89, 0, MATCH(F72,$G$67:$AA$67,0))+C41} -> 5.788125 | F72: 2120 | G72: =IF(G$36>=$F72,$E72*INDEX($F$13:$Z$13,MATCH(G$67-$F72,$F$12:$Z$12,0)),0) -> 0 | H72: =IF(H$36>=$F72,$E72*INDEX($F$13:$Z$13,MATCH(H$67-$F72,$F$12:$Z$12,0)),0) -> 0 | I72: =IF(I$36>=$F72,$E72*INDEX($F$13:$Z$13,MATCH(I$67-$F72,$F$12:$Z$12,0)),0) -> 0 | J72: =IF(J$36>=$F72,$E72*INDEX($F$13:$Z$13,MATCH(J$67-$F72,$F$12:$Z$12,0)),0) -> 0 | K72: =IF(K$36>=$F72,$E72*INDEX($F$13:$Z$13,MATCH(K$67-$F72,$F$12:$Z$12,0)),0) -> 0 | L72: =IF(L$36>=$F72,$E72*INDEX($F$13:$Z$13,MATCH(L$67-$F72,$F$12:$Z$12,0)),0) -> 0 | M72: =IF(M$36>=$F72,$E72*INDEX($F$13:$Z$13,MATCH(M$67-$F72,$F$12:$Z$12,0)),0) -> 0 | N72: =IF(N$36>=$F72,$E72*INDEX($F$13:$Z$13,MATCH(N$67-$F72,$F$12:$Z$12,0)),0) -> 0 | ... AA72: =IF(AA$36>=$F72,$E72*INDEX($F$13:$Z$13,MATCH(AA$67-$F72,$F$12:$Z$12,0)),0) -> 0 | AD72: 5.788125 | AE72: 2120 | AF72: =IF(G$36>=$F72,$AD72-SUM($G72:G72),0) -> 0 | AG72: =IF(H$36>=$F72,$AD72-SUM($G72:H72),0) -> 0 | AH72: =IF(I$36>=$F72,$AD72-SUM($G72:I72),0) -> 0 | AI72: =IF(J$36>=$F72,$AD72-SUM($G72:J72),0) -> 0 | AJ72: =IF(K$36>=$F72,$AD72-SUM($G72:K72),0) -> 5.788125 | AK72: =IF(L$36>=$F72,$AD72-SUM($G72:L72),0) -> 5.788125 | AL72: =IF(M$36>=$F72,$AD72-SUM($G72:M72),0) -> 5.788125 | AM72: =IF(N$36>=$F72,$AD72-SUM($G72:N72),0) -> 5.788125 | ... AZ72: =IF(AA$36>=$F72,$AD72-SUM($G72:AA72),0) -> 0.0010264458
B73: =B72+C73 -> 85.45388 | C73: =E42-E73 -> 17.248834 | D73: =D72+E73 -> 139.13286 | E73: {=INDEX($G$89:$AA$89, 0, MATCH(F73,$G$67:$AA$67,0))+C42} -> 17.582235 | F73: 2130 | G73: =IF(G$36>=$F73,$E73*INDEX($F$13:$Z$13,MATCH(G$67-$F73,$F$12:$Z$12,0)),0) -> 0 | H73: =IF(H$36>=$F73,$E73*INDEX($F$13:$Z$13,MATCH(H$67-$F73,$F$12:$Z$12,0)),0) -> 0 | I73: =IF(I$36>=$F73,$E73*INDEX($F$13:$Z$13,MATCH(I$67-$F73,$F$12:$Z$12,0)),0) -> 0 | J73: =IF(J$36>=$F73,$E73*INDEX($F$13:$Z$13,MATCH(J$67-$F73,$F$12:$Z$12,0)),0) -> 0 | K73: =IF(K$36>=$F73,$E73*INDEX($F$13:$Z$13,MATCH(K$67-$F73,$F$12:$Z$12,0)),0) -> 0 | L73: =IF(L$36>=$F73,$E73*INDEX($F$13:$Z$13,MATCH(L$67-$F73,$F$12:$Z$12,0)),0) -> 0 | M73: =IF(M$36>=$F73,$E73*INDEX($F$13:$Z$13,MATCH(M$67-$F73,$F$12:$Z$12,0)),0) -> 0 | N73: =IF(N$36>=$F73,$E73*INDEX($F$13:$Z$13,MATCH(N$67-$F73,$F$12:$Z$12,0)),0) -> 0 | ... AA73: =IF(AA$36>=$F73,$E73*INDEX($F$13:$Z$13,MATCH(AA$67-$F73,$F$12:$Z$12,0)),0) -> 0 | AD73: 17.582235 | AE73: 2130 | AF73: =IF(G$36>=$F73,$AD73-SUM($G73:G73),0) -> 0 | AG73: =IF(H$36>=$F73,$AD73-SUM($G73:H73),0) -> 0 | AH73: =IF(I$36>=$F73,$AD73-SUM($G73:I73),0) -> 0 | AI73: =IF(J$36>=$F73,$AD73-SUM($G73:J73),0) -> 0 | AJ73: =IF(K$36>=$F73,$AD73-SUM($G73:K73),0) -> 0 | AK73: =IF(L$36>=$F73,$AD73-SUM($G73:L73),0) -> 17.582235 | AL73: =IF(M$36>=$F73,$AD73-SUM($G73:M73),0) -> 17.582235 | AM73: =IF(N$36>=$F73,$AD73-SUM($G73:N73),0) -> 17.582235 | ... AZ73: =IF(AA$36>=$F73,$AD73-SUM($G73:AA73),0) -> 0.0031179719
...

Sheet Hummus Town, constant stock
E1: Building Designers in Hummus Town want to explore what would happen if they make their buildings last longer. Change the "Years Shifted Later" cell to see, and change the "Constant Stock of Homes"
E3: Candy Town Lifespan Distribution
E4: Lifespan | F4: 0 | G4: 10 | H4: 20 | I4: 30 | J4: 40 | K4: 50 | L4: 60 | M4: 70 | N4: 80 | O4: 90 | P4: 100 | Q4: 110 | R4: 120 | S4: 130 | T4: 140 | U4: 150 | V4: 160 | W4: 170 | X4: 180 | Y4: 190 | Z4: 200
E5: Percent | F5: 0 | G5: 0 | H5: 0.11504703 | I5: 0.25784901 | J5: 0.27123382 | K5: 0.19410333 | L5: 0.10280688 | M5: 0.04165639 | N5: 0.013126206 | O5: 0.004 | P5: 0 | Q5: 0 | R5: 0 | S5: 0 | T5: 0 | U5: 0 | V5: 0 | W5: 0 | X5: 0 | Y5: 0 | Z5: 0
E7: Years Shifted Later: | G7: 40 | H7: (must be multiple of 10)
E8: Hummus Town Longer Lifespan Distribution
E9: Lifespan | F9: 0 | G9: 10 | H9: 20 | I9: 30 | J9: 40 | K9: 50 | L9: 60 | M9: 70 | N9: 80 | O9: 90 | P9: 100 | Q9: 110 | R9: 120 | S9: 130 | T9: 140 | U9: 150 | V9: 160 | W9: 170 | X9: 180 | Y9: 190 | Z9: 200
E10: Percent | F10: =IFERROR(INDEX($F$5:$O$5,MATCH(F$9-$G$7,$F$4:$O$4,0)),0) -> 0 | G10: =IFERROR(INDEX($F$5:$O$5,MATCH(G$9-$G$7,$F$4:$O$4,0)),0) -> 0 | H10: =IFERROR(INDEX($F$5:$O$5,MATCH(H$9-$G$7,$F$4:$O$4,0)),0) -> 0 | I10: =IFERROR(INDEX($F$5:$O$5,MATCH(I$9-$G$7,$F$4:$O$4,0)),0) -> 0 | J10: =IFERROR(INDEX($F$5:$O$5,MATCH(J$9-$G$7,$F$4:$O$4,0)),0) -> 0 | K10: =IFERROR(INDEX($F$5:$O$5,MATCH(K$9-$G$7,$F$4:$O$4,0)),0) -> 0 | L10: =IFERROR(INDEX($F$5:$O$5,MATCH(L$9-$G$7,$F$4:$O$4,0)),0) -> 0.11504703 | M10: =IFERROR(INDEX($F$5:$O$5,MATCH(M$9-$G$7,$F$4:$O$4,0)),0) -> 0.25784901 | ... Z10: =IFERROR(INDEX($F$5:$O$5,MATCH(Z$9-$G$7,$F$4:$O$4,0)),0) -> 0
E12: Constant stock of homes: | H12: 1000
